Workbook

Sheet DASBOARD
B3: RIEPILOGO ORDINI
B5: Marketplace | C5: (Tutto)
B6: Paese (Mercato) | C6: (Tutto)
B7: Data ordine | C7: (Tutto)
B8: Stato ordine | C8: Non pagato
B10: Fatturato (Lordo) | C10: Costo totale | D10: Utile
B11: 6370.43 | C11: 4475.9756 | D11: 1894.4544

Sheet Ordini
A1: Data ordine | B1: Marketplace | C1: Paese (Mercato) | D1: Order ID (Codice Market) | E1: Prodotto (SKU o nome) | F1: Quantità ordinata | G1: Fatturato (Lordo) | H1: Iva (%) | I1: Imponibile | J1: Fee (€) | K1: Costo prodotto | L1: Costo logistico | M1: Stato ordine | N1: Quantità resi effettiva | O1: Costo totale | P1: Utile | Q1: Decisione | R1: Note
A2: 46113 | B2: Amazon | C2: IT | D2: 403-0703493-4588300 | E2: Decespugliatore a batteria - KD5124 | F2: 1 | G2: 39.99 | H2: 0 | I2: =Ordini!$G2/(1+Ordini!$H2) -> 39.99 | J2: 7.54 | K2: 15.1 | L2: 4.85 | M2: Pagato | O2: =Ordini!$K2+Ordini!$J2+Ordini!$L2 -> 27.49 | P2: =Ordini!$I2-Ordini!$O2 -> 12.5 | Q2: =IF(Ordini!$P2<0,"DA EVITARE","OK") -> OK
A3: 02/04/2026 | B3: Amazon | C3: IT | D3: 171-9083991-8149103 | E3: Decespugliatore a batteria - KD5124 | F3: 1 | G3: 39.99 | H3: 0 | I3: =Ordini!$G3/(1+Ordini!$H3) -> 39.99 | J3: 7.54 | K3: 15.1 | L3: 4.85 | M3: Pagato | O3: =Ordini!$K3+Ordini!$J3+Ordini!$L3 -> 27.49 | P3: =Ordini!$I3-Ordini!$O3 -> 12.5 | Q3: =IF(Ordini!$P3<0,"DA EVITARE","OK") -> OK
A4: 02/04/2026 | B4: Amazon | C4: IT | D4: 171-9068873-5509917 | E4: Miscelatore Per Malta - KD541 | F4: 1 | G4: 51.99 | H4: 0 | I4: =Ordini!$G4/(1+Ordini!$H4) -> 51.99 | J4: 8.49 | K4: 20.97 | L4: 4.85 | M4: Pagato | O4: =Ordini!$K4+Ordini!$J4+Ordini!$L4 -> 34.31 | P4: =Ordini!$I4-Ordini!$O4 -> 17.68 | Q4: =IF(Ordini!$P4<0,"DA EVITARE","OK") -> OK
A5: 02/04/2026 | B5: Amazon | C5: IT | D5: 405-5126325-5508363 | E5: Decespugliatore a batteria - KD5124 | F5: 1 | G5: 39.99 | H5: 0 | I5: =Ordini!$G5/(1+Ordini!$H5) -> 39.99 | J5: 7.54 | K5: 15.1 | L5: 4.85 | M5: Pagato | O5: =Ordini!$K5+Ordini!$J5+Ordini!$L5 -> 27.49 | P5: =Ordini!$I5-Ordini!$O5 -> 12.5 | Q5: =IF(Ordini!$P5<0,"DA EVITARE","OK") -> OK
A6: 02/04/2026 | B6: Amazon | C6: IT | D6: 405-2974653-4082717 | E6: Decespugliatore a batteria - KD5124 | F6: 1 | G6: 39.99 | H6: 0 | I6: =Ordini!$G6/(1+Ordini!$H6) -> 39.99 | J6: 7.54 | K6: 15.1 | L6: 4.85 | M6: Pagato | O6: =Ordini!$K6+Ordini!$J6+Ordini!$L6 -> 27.49 | P6: =Ordini!$I6-Ordini!$O6 -> 12.5 | Q6: =IF(Ordini!$P6<0,"DA EVITARE","OK") -> OK
A7: 02/04/2026 | B7: Temu | C7: IT | D7: PO-098-14133980777593211 | E7: Motosega a batteria 12" - KD5125 | F7: 1 | G7: 59.72 | H7: 0 | I7: =Ordini!$G7/(1+Ordini!$H7) -> 59.72 | J7: 0 | K7: 32.05 | L7: 5.87 | M7: Pagato | O7: =Ordini!$K7+Ordini!$J7+Ordini!$L7 -> 37.92 | P7: =Ordini!$I7-Ordini!$O7 -> 21.8 | Q7: =IF(Ordini!$P7<0,"DA EVITARE","OK") -> OK
A8: 02/04/2026 | B8: Temu | C8: IT | D8: PO-098-13881093473911711 | E8: Cuociuova in Acciaio Inox - KD4118 | F8: 1 | G8: 23.68 | H8: 0 | I8: =Ordini!$G8/(1+Ordini!$H8) -> 23.68 | J8: 0 | K8: 10.82 | L8: 4.77 | M8: Pagato | O8: =Ordini!$K8+Ordini!$J8+Ordini!$L8 -> 15.59 | P8: =Ordini!$I8-Ordini!$O8 -> 8.09 | Q8: =IF(Ordini!$P8<0,"DA EVITARE","OK") -> OK
A9: 02/04/2026 | B9: eBay | C9: IT | D9: 20-14434-30598 | E9: Frullatore Elettrico a Immersione - KD4110 | F9: 1 | G9: 39.99 | H9: 0 | I9: =Ordini!$G9/(1+Ordini!$H9) -> 39.99 | J9: 3.89 | K9: 18.48 | L9: 4.77 | M9: Pagato | O9: =Ordini!$K9+Ordini!$J9+Ordini!$L9 -> 27.14 | P9: =Ordini!$I9-Ordini!$O9 -> 12.85 | Q9: =IF(Ordini!$P9<0,"DA EVITARE","OK") -> OK
A10: 03/04/2026 | B10: Leroy Merlin | C10: IT | D10: 005-26091L15471-A | E10: DFL_308440 | F10: 2 | G10: 18.76 | H10: 0 | I10: =Ordini!$G10/(1+Ordini!$H10) -> 18.76 | J10: 2.81 | K10: 4.5384 | L10: 4.36 | M10: Pagato | O10: =Ordini!$K10+Ordini!$J10+Ordini!$L10 -> 11.7084 | P10: =Ordini!$I10-Ordini!$O10 -> 7.0516 | Q10: =IF(Ordini!$P10<0,"DA EVITARE","OK") -> OK
A11: 03/04/2026 | B11: Amazon | C11: IT | D11: 171-1434651-1557114 | E11: Idealux_8021696308227 | F11: 4 | G11: 48 | H11: 0 | I11: =Ordini!$G11/(1+Ordini!$H11) -> 48 | J11: 9.05 | K11: 30.76 | L11: 4.77 | M11: Pagato | O11: =Ordini!$K11+Ordini!$J11+Ordini!$L11 -> 44.58 | P11: =Ordini!$I11-Ordini!$O11 -> 3.42 | Q11: =IF(Ordini!$P11<0,"DA EVITARE","OK") -> OK
A12: 03/04/2026 | B12: Temu | C12: IT | D12: PO-098-08685015895674008 | E12: Barra e lama - KD10152 | F12: 1 | G12: 21.53 | H12: 0 | I12: =Ordini!$G12/(1+Ordini!$H12) -> 21.53 | J12: 0 | K12: 8.08 | L12: 4.77 | M12: Pagato | O12: =Ordini!$K12+Ordini!$J12+Ordini!$L12 -> 12.85 | P12: =Ordini!$I12-Ordini!$O12 -> 8.68 | Q12: =IF(Ordini!$P12<0,"DA EVITARE","OK") -> OK
A13: 03/04/2026 | B13: Temu | C13: IT | D13: PO-098-08842739400312172 | E13: DFL_805061 | F13: 1 | G13: 54.19 | H13: 0 | I13: =Ordini!$G13/(1+Ordini!$H13) -> 54.19 | J13: 0 | K13: 42.5414 | L13: 12.5 | M13: Pagato | O13: =Ordini!$K13+Ordini!$J13+Ordini!$L13 -> 55.0414 | P13: =Ordini!$I13-Ordini!$O13 -> -0.8514 | Q13: =IF(Ordini!$P13<0,"DA EVITARE","OK") -> DA EVITARE
A14: 03/04/2026 | B14: eBay | C14: IT | D14: 27-14428-41941 | E14: Miscelatore Per Malta - KD541 | F14: 1 | G14: 46.03 | H14: 0 | I14: =Ordini!$G14/(1+Ordini!$H14) -> 46.03 | J14: 4.42 | K14: 20.97 | L14: 4.85 | M14: Pagato | O14: =Ordini!$K14+Ordini!$J14+Ordini!$L14 -> 30.24 | P14: =Ordini!$I14-Ordini!$O14 -> 15.79 | Q14: =IF(Ordini!$P14<0,"DA EVITARE","OK") -> OK
A15: 04/04/2026 | B15: Kaufland | C15: FR | D15: MQD8795 | E15: Idealux_8021696122854 | F15: 1 | G15: 42.24 | H15: 0 | I15: =Ordini!$G15/(1+Ordini!$H15) -> 42.24 | J15: 5.49 | K15: 19.52 | L15: 9.01 | M15: Pagato | O15: =Ordini!$K15+Ordini!$J15+Ordini!$L15 -> 34.02 | P15: =Ordini!$I15-Ordini!$O15 -> 8.22 | Q15: =IF(Ordini!$P15<0,"DA EVITARE","OK") -> OK
A16: 46116 | B16: Kaufland | C16: DE | D16: MDZCR95 | E16: Idealux_8021696268095 | F16: 1 | G16: 207.1 | H16: 0 | I16: =Ordini!$G16/(1+Ordini!$H16) -> 207.1 | J16: 26.92 | K16: 124.26 | L16: 8.08 | M16: Pagato | O16: =Ordini!$K16+Ordini!$J16+Ordini!$L16 -> 159.26 | P16: =Ordini!$I16-Ordini!$O16 -> 47.84 | Q16: =IF(Ordini!$P16<0,"DA EVITARE","OK") -> OK
A17: 04/04/2026 | B17: Amazon | C17: IT | D17: 408-2513706-1853919 | E17: Motosega a batteria 12" - KD5125 | F17: 1 | G17: 68.9 | H17: 0 | I17: =Ordini!$G17/(1+Ordini!$H17) -> 68.9 | J17: 11.26 | K17: 32.05 | L17: 5.87 | M17: Pagato | O17: =Ordini!$K17+Ordini!$J17+Ordini!$L17 -> 49.18 | P17: =Ordini!$I17-Ordini!$O17 -> 19.72 | Q17: =IF(Ordini!$P17<0,"DA EVITARE","OK") -> OK
A18: 04/04/2026 | B18: Temu | C18: IT | D18: PO-098-08583267169910582 | E18: Cuociuova in Acciaio Inox - KD4118 | F18: 1 | G18: 23.68 | H18: 0 | I18: =Ordini!$G18/(1+Ordini!$H18) -> 23.68 | J18: 0 | K18: 10.82 | L18: 4.77 | M18: Pagato | O18: =Ordini!$K18+Ordini!$J18+Ordini!$L18 -> 15.59 | P18: =Ordini!$I18-Ordini!$O18 -> 8.09 | Q18: =IF(Ordini!$P18<0,"DA EVITARE","OK") -> OK
A19: 05/04/2026 | B19: Amazon | C19: IT | D19: 407-9002825-8868322 | E19: Idealux_8021696096728 | F19: 2 | G19: 52 | H19: 0 | I19: =Ordini!$G19/(1+Ordini!$H19) -> 52 | J19: 9.79 | K19: 30.77 | L19: 4.77 | M19: Pagato | O19: =Ordini!$K19+Ordini!$J19+Ordini!$L19 -> 45.33 | P19: =Ordini!$I19-Ordini!$O19 -> 6.67 | Q19: =IF(Ordini!$P19<0,"DA EVITARE","OK") -> OK
A20: 05/04/2026 | B20: Amazon | C20: IT | D20: 405-5798018-5661920 | E20: Idealux_8021696115320 | F20: 4 | G20: 160 | H20: 0 | I20: =Ordini!$G20/(1+Ordini!$H20) -> 160 | J20: 30.16 | K20: 94.67 | L20: 4.77 | M20: Pagato | O20: =Ordini!$K20+Ordini!$J20+Ordini!$L20 -> 129.6 | P20: =Ordini!$I20-Ordini!$O20 -> 30.4 | Q20: =IF(Ordini!$P20<0,"DA EVITARE","OK") -> OK
A21: 05/04/2026 | B21: Amazon | C21: IT | D21: 402-2940974-1252331 | E21: Miscelatore Per Malta - KD541 | F21: 1 | G21: 51.99 | H21: 0 | I21: =Ordini!$G21/(1+Ordini!$H21) -> 51.99 | J21: 8.49 | K21: 20.97 | L21: 4.85 | M21: Pagato | O21: =Ordini!$K21+Ordini!$J21+Ordini!$L21 -> 34.31 | P21: =Ordini!$I21-Ordini!$O21 -> 17.68 | Q21: =IF(Ordini!$P21<0,"DA EVITARE","OK") -> OK
A22: 05/04/2026 | B22: Amazon | C22: IT | D22: 408-1873729-0797121 | E22: Miscelatore Per Malta - KD541 | F22: 1 | G22: 51.99 | H22: 0 | I22: =Ordini!$G22/(1+Ordini!$H22) -> 51.99 | J22: 8.49 | K22: 20.97 | L22: 4.85 | M22: Pagato | O22: =Ordini!$K22+Ordini!$J22+Ordini!$L22 -> 34.31 | P22: =Ordini!$I22-Ordini!$O22 -> 17.68 | Q22: =IF(Ordini!$P22<0,"DA EVITARE","OK") -> OK
A23: 05/04/2026 | B23: Temu | C23: IT | D23: PO-098-00623920809592840 | E23: DFL_6129346 | F23: 1 | G23: 17.27 | H23: 0 | I23: =Ordini!$G23/(1+Ordini!$H23) -> 17.27 | J23: 0 | K23: 10.919 | L23: 4.36 | M23: Pagato | O23: =Ordini!$K23+Ordini!$J23+Ordini!$L23 -> 15.279 | P23: =Ordini!$I23-Ordini!$O23 -> 1.991 | Q23: =IF(Ordini!$P23<0,"DA EVITARE","OK") -> OK
A24: 05/04/2026 | B24: eBay | C24: IT | D24: 25-14439-05404 | E24: Miscelatore Per Malta - KD541 | F24: 1 | G24: 43.73 | H24: 0 | I24: =Ordini!$G24/(1+Ordini!$H24) -> 43.73 | J24: 4.21 | K24: 20.97 | L24: 4.85 | M24: Pagato | O24: =Ordini!$K24+Ordini!$J24+Ordini!$L24 -> 30.03 | P24: =Ordini!$I24-Ordini!$O24 -> 13.7 | Q24: =IF(Ordini!$P24<0,"DA EVITARE","OK") -> OK
A25: 06/04/2026 | B25: Amazon | C25: IT | D25: 407-7524359-7607559 | E25: DFL_5115472 | F25: 1 | G25: 23.5 | H25: 0 | I25: =Ordini!$G25/(1+Ordini!$H25) -> 23.5 | J25: 3.84 | K25: 10.5042 | L25: 4.36 | M25: Pagato | O25: =Ordini!$K25+Ordini!$J25+Ordini!$L25 -> 18.7042 | P25: =Ordini!$I25-Ordini!$O25 -> 4.7958 | Q25: =IF(Ordini!$P25<0,"DA EVITARE","OK") -> OK
A26: 06/04/2026 | B26: Temu | C26: IT | D26: PO-098-11163278853751652 | E26: Barra e lama - KD10152 | F26: 1 | G26: 21.53 | H26: 0 | I26: =Ordini!$G26/(1+Ordini!$H26) -> 21.53 | J26: 0 | K26: 8.08 | L26: 4.77 | M26: Pagato | O26: =Ordini!$K26+Ordini!$J26+Ordini!$L26 -> 12.85 | P26: =Ordini!$I26-Ordini!$O26 -> 8.68 | Q26: =IF(Ordini!$P26<0,"DA EVITARE","OK") -> OK
A27: 06/04/2026 | B27: eBay | C27: IT | D27: 01-14478-64734 | E27: Miscelatore Per Malta - KD541 | F27: 1 | G27: 46 | H27: 0 | I27: =Ordini!$G27/(1+Ordini!$H27) -> 46 | J27: 4.42 | K27: 20.97 | L27: 4.85 | M27: Pagato | O27: =Ordini!$K27+Ordini!$J27+Ordini!$L27 -> 30.24 | P27: =Ordini!$I27-Ordini!$O27 -> 15.76 | Q27: =IF(Ordini!$P27<0,"DA EVITARE","OK") -> OK
A28: 07/04/2026 | B28: Amazon | C28: IT | D28: 408-5892501-7549110 | E28: Microonde 30L - KD4111 | F28: 1 | G28: 89.99 | H28: 0 | I28: =Ordini!$G28/(1+Ordini!$H28) -> 89.99 | J28: 16.98 | K28: 38.61 | L28: 8.07 | M28: Pagato | O28: =Ordini!$K28+Ordini!$J28+Ordini!$L28 -> 63.66 | P28: =Ordini!$I28-Ordini!$O28 -> 26.33 | Q28: =IF(Ordini!$P28<0,"DA EVITARE","OK") -> OK
... A41: 11/04/2026 | B41: Temu | C41: IT | D41: PO-098-09673381391991191 | E41: DFL_805061 | F41: 1 | G41: 54.19 | H41: 0 | I41: =Ordini!$G41/(1+Ordini!$H41) -> 54.19 | J41: 0 | K41: 42.5414 | L41: 12.5 | M41: Pagato | O41: =Ordini!$K41+Ordini!$J41+Ordini!$L41 -> 55.0414 | P41: =Ordini!$I41-Ordini!$O41 -> -0.8514 | Q41: =IF(Ordini!$P41<0,"DA EVITARE","OK") -> DA EVITARE
A42: 46123 | B42: Leroy Merlin | C42: IT | D42: 005-26101L409-A | E42: DFL_406754 | F42: 1 | G42: 8.57 | H42: 0 | I42: =Ordini!$G42/(1+Ordini!$H42) -> 8.57 | J42: 0.86 | K42: 0.549 | L42: 4.36 | M42: Pagato | O42: =Ordini!$K42+Ordini!$J42+Ordini!$L42 -> 5.769 | P42: =Ordini!$I42-Ordini!$O42 -> 2.801 | Q42: =IF(Ordini!$P42<0,"DA EVITARE","OK") -> OK
A43: 12/04/2026 | B43: Amazon | C43: IT | D43: 402-4903117-5330701 | E43: DFL_6000652 | F43: 1 | G43: 44.34 | H43: 0 | I43: =Ordini!$G43/(1+Ordini!$H43) -> 44.34 | J43: 8.35 | K43: 28.853 | L43: 4.85 | M43: Pagato | O43: =Ordini!$K43+Ordini!$J43+Ordini!$L43 -> 42.053 | P43: =Ordini!$I43-Ordini!$O43 -> 2.287 | Q43: =IF(Ordini!$P43<0,"DA EVITARE","OK") -> OK
A44: 12/04/2026 | B44: Temu | C44: IT | D44: PO-098-21048769216633978 | E44: DFL_6129340 | F44: 1 | G44: 13.8 | H44: 0 | I44: =Ordini!$G44/(1+Ordini!$H44) -> 13.8 | J44: 0 | K44: 5.856 | L44: 4.36 | M44: Pagato | O44: =Ordini!$K44+Ordini!$J44+Ordini!$L44 -> 10.216 | P44: =Ordini!$I44-Ordini!$O44 -> 3.584 | Q44: =IF(Ordini!$P44<0,"DA EVITARE","OK") -> OK
A45: 12/04/2026 | B45: Temu | C45: IT | D45: PO-098-20775638431351574 | E45: DFL_805061 | F45: 1 | G45: 54.19 | H45: 0 | I45: =Ordini!$G45/(1+Ordini!$H45) -> 54.19 | J45: 0 | K45: 42.5414 | L45: 12.5 | M45: Pagato | O45: =Ordini!$K45+Ordini!$J45+Ordini!$L45 -> 55.0414 | P45: =Ordini!$I45-Ordini!$O45 -> -0.8514 | Q45: =IF(Ordini!$P45<0,"DA EVITARE","OK") -> DA EVITARE
A46: 12/04/2026 | B46: eBay | C46: IT | D46: 03-14504-82412 | E46: Crick auto 2,5 T - WDS2490 | F46: 1 | G46: 55 | H46: 0 | I46: =Ordini!$G46/(1+Ordini!$H46) -> 55 | J46: 5.22 | K46: 24.03 | L46: 8.4 | M46: Pagato | O46: =Ordini!$K46+Ordini!$J46+Ordini!$L46 -> 37.65 | P46: =Ordini!$I46-Ordini!$O46 -> 17.35 | Q46: =IF(Ordini!$P46<0,"DA EVITARE","OK") -> OK
A47: 46124 | B47: Leroy Merlin | C47: IT | D47: 005-26102L11873-A | E47: DFL_900610 | F47: 1 | G47: 14.51 | H47: 0 | I47: =Ordini!$G47/(1+Ordini!$H47) -> 14.51 | J47: 2.18 | K47: 4.88 | L47: 4.36 | M47: Pagato | O47: =Ordini!$K47+Ordini!$J47+Ordini!$L47 -> 11.42 | P47: =Ordini!$I47-Ordini!$O47 -> 3.09 | Q47: =IF(Ordini!$P47<0,"DA EVITARE","OK") -> OK
A48: 14/04/2026 | B48: Amazon | C48: IT | D48: 405-6360802-8896358 | E48: DFL_612527 | F48: 2 | G48: 29.4 | H48: 0 | I48: =Ordini!$G48/(1+Ordini!$H48) -> 29.4 | J48: 4.79 | K48: 14.8352 | L48: 4.36 | M48: Pagato | O48: =Ordini!$K48+Ordini!$J48+Ordini!$L48 -> 23.9852 | P48: =Ordini!$I48-Ordini!$O48 -> 5.4148 | Q48: =IF(Ordini!$P48<0,"DA EVITARE","OK") -> OK
A49: 14/04/2026 | B49: Amazon | C49: IT | D49: 404-0082468-0194704 | E49: DFL_612821 | F49: 1 | G49: 13.42 | H49: 0 | I49: =Ordini!$G49/(1+Ordini!$H49) -> 13.42 | J49: 2.52 | K49: 2.7816 | L49: 4.36 | M49: Pagato | O49: =Ordini!$K49+Ordini!$J49+Ordini!$L49 -> 9.6616 | P49: =Ordini!$I49-Ordini!$O49 -> 3.7584 | Q49: =IF(Ordini!$P49<0,"DA EVITARE","OK") -> OK
A50: 46127 | B50: Leroy Merlin | C50: IT | D50: 005-26104L3011-A | E50: DFL_1045434 | F50: 2 | G50: 183.96 | H50: 0 | I50: =Ordini!$G50/(1+Ordini!$H50) -> 183.96 | J50: 22.08 | K50: 106.4328 | L50: 23.24 | M50: Pagato | O50: =Ordini!$K50+Ordini!$J50+Ordini!$L50 -> 151.7528 | P50: =Ordini!$I50-Ordini!$O50 -> 32.2072 | Q50: =IF(Ordini!$P50<0,"DA EVITARE","OK") -> OK
A51: 15/04/2026 | B51: Amazon | C51: IT | D51: 405-4498096-1823549 | E51: DFL_6237209 | F51: 1 | G51: 17.61 | H51: 0 | I51: =Ordini!$G51/(1+Ordini!$H51) -> 17.61 | J51: 1.77 | K51: 5.8194 | L51: 4.36 | M51: Pagato | O51: =Ordini!$K51+Ordini!$J51+Ordini!$L51 -> 11.9494 | P51: =Ordini!$I51-Ordini!$O51 -> 5.6606 | Q51: =IF(Ordini!$P51<0,"DA EVITARE","OK") -> OK
A52: 15/04/2026 | B52: Amazon | C52: IT | D52: 408-8782064-0290726 | E52: DFL_4048740 | F52: 1 | G52: 28.31 | H52: 0 | I52: =Ordini!$G52/(1+Ordini!$H52) -> 28.31 | J52: 5.34 | K52: 1.3908 | L52: 4.36 | M52: Pagato | O52: =Ordini!$K52+Ordini!$J52+Ordini!$L52 -> 11.0908 | P52: =Ordini!$I52-Ordini!$O52 -> 17.2192 | Q52: =IF(Ordini!$P52<0,"DA EVITARE","OK") -> OK
...

Sheet Prodotti Magazzino
A1: Prodotto (SKU o nome) | B1: Costo prodotto | C1: Costo reale | D1: Stock iniziale | E1: Stock (A magazzino) | F1: Vendite totali | G1: Resi | H1: Lead time (giorni) | I1: Vendite giornaliere | K1: Copertura stock (Giorni) | L1: Punto di riordino (Stock minimo da avere) | M1: Quantità da ordinare | N1: Allert Riordino | O1: Valore stock | P1: Peso lordo | Q1: Volume
A2: Smerigliatrice angolare - WDS2135 | B2: 17.53 | C2: =IFERROR( IF(_xlfn.XLOOKUP(A2,Carichi!B:B,Carichi!D:D)="", B2, _xlfn.XLOOKUP(A2,Carichi!B:B,Carichi!D:D) ), B2 ) -> 17.53 | D2: 0 | E2: =D2 +SUMIF(Carichi!B:B,A2,Carichi!C:C)-F2+G2 -> 0 | F2: =SUMIF(Ordini!E:E,TRIM(A2),Ordini!F:F) -> 0 | G2: =SUMIFS(Ordini!N:N,Ordini!E:E,A2,Ordini!M:M,"Reso")+SUMIFS(Ordini!N:N,Ordini!E:E,A2,Ordini!M:M,"RimborsatoReso") -> 0 | H2: 10 | I2: =IFERROR(SUMIFS(Ordini!F:F,Ordini!E:E,A2)/30,1) -> 0 | J2: =IF(I2<=0,"NESSUNA ROTAZIONE","ROT: 1 pz ogni "&ROUND(1/I2,0)&" gg") -> NESSUNA ROTAZIONE | K2: =IF(OR('Prodotti Magazzino'!$I2=0,'Prodotti Magazzino'!$I2=""), "NESSUNA VENDITA", ROUND('Prodotti Magazzino'!$E2/'Prodotti Magazzino'!$I2,0) ) -> NESSUNA VENDITA | L2: =ROUND(IF('Prodotti Magazzino'!$I2<=0,0,'Prodotti Magazzino'!$I2*('Prodotti Magazzino'!$H2+7)),0) -> 0 | M2: =ROUND(MAX(0,(I2*(H2+14))-E2),0) -> 0 | N2: =IF(E2 < I2*H2,"ORDINA SUBITO", IF(E2 < I2*(H2+14),"PREPARA", "OK")) -> OK | O2: ='Prodotti Magazzino'!$E2*'Prodotti Magazzino'!$B2 -> 0
A3: Compressore a batteria - KD5497 | B3: =11.11+1.62 -> 12.73 | C3: =IFERROR( IF(_xlfn.XLOOKUP(A3,Carichi!B:B,Carichi!D:D)="", B3, _xlfn.XLOOKUP(A3,Carichi!B:B,Carichi!D:D) ), B3 ) -> 12.73 | D3: 0 | E3: =D3 +SUMIF(Carichi!B:B,A3,Carichi!C:C)-F3+G3 -> 0 | F3: =SUMIF(Ordini!E:E,TRIM(A3),Ordini!F:F) -> 0 | G3: =SUMIFS(Ordini!N:N,Ordini!E:E,A3,Ordini!M:M,"Reso")+SUMIFS(Ordini!N:N,Ordini!E:E,A3,Ordini!M:M,"RimborsatoReso") -> 0 | H3: 10 | I3: =IFERROR(SUMIFS(Ordini!F:F,Ordini!E:E,A3)/30,1) -> 0 | J3: =IF(I3<=0,"NESSUNA ROTAZIONE","ROT: 1 pz ogni "&ROUND(1/I3,0)&" gg") -> NESSUNA ROTAZIONE | K3: =IF(OR('Prodotti Magazzino'!$I3=0,'Prodotti Magazzino'!$I3=""), "NESSUNA VENDITA", ROUND('Prodotti Magazzino'!$E3/'Prodotti Magazzino'!$I3,0) ) -> NESSUNA VENDITA | L3: =ROUND(IF('Prodotti Magazzino'!$I3<=0,0,'Prodotti Magazzino'!$I3*('Prodotti Magazzino'!$H3+7)),0) -> 0 | M3: =ROUND(MAX(0,(I3*(H3+14))-E3),0) -> 0 | N3: =IF(E3 < I3*H3,"ORDINA SUBITO", IF(E3 < I3*(H3+14),"PREPARA", "OK")) -> OK | O3: ='Prodotti Magazzino'!$E3*'Prodotti Magazzino'!$B3 -> 0
A4: Miscelatore Per Malta - KD541 | B4: =19.35+1.62 -> 20.97 | C4: =IFERROR( IF(_xlfn.XLOOKUP(A4,Carichi!B:B,Carichi!D:D)="", B4, _xlfn.XLOOKUP(A4,Carichi!B:B,Carichi!D:D) ), B4 ) -> 22.95 | D4: 5 | E4: =D4 +SUMIF(Carichi!B:B,A4,Carichi!C:C)-F4+G4 -> -1 | F4: =SUMIF(Ordini!E:E,TRIM(A4),Ordini!F:F) -> 26 | G4: =SUMIFS(Ordini!N:N,Ordini!E:E,A4,Ordini!M:M,"Reso")+SUMIFS(Ordini!N:N,Ordini!E:E,A4,Ordini!M:M,"RimborsatoReso") -> 0 | H4: 10 | I4: =IFERROR(SUMIFS(Ordini!F:F,Ordini!E:E,A4)/30,1) -> 0.86666667 | J4: =IF(I4<=0,"NESSUNA ROTAZIONE","ROT: 1 pz ogni "&ROUND(1/I4,0)&" gg") -> ROT: 1 pz ogni 1 gg | K4: =IF(OR('Prodotti Magazzino'!$I4=0,'Prodotti Magazzino'!$I4=""), "NESSUNA VENDITA", ROUND('Prodotti Magazzino'!$E4/'Prodotti Magazzino'!$I4,0) ) -> -1 | L4: =ROUND(IF('Prodotti Magazzino'!$I4<=0,0,'Prodotti Magazzino'!$I4*('Prodotti Magazzino'!$H4+7)),0) -> 15 | M4: =ROUND(MAX(0,(I4*(H4+14))-E4),0) -> 22 | N4: =IF(E4 < I4*H4,"ORDINA SUBITO", IF(E4 < I4*(H4+14),"PREPARA", "OK")) -> ORDINA SUBITO | O4: ='Prodotti Magazzino'!$E4*'Prodotti Magazzino'!$B4 -> -20.97
A5: Fornello Elettrico Portatile - KD4139 | B5: =3.84+1.62 -> 5.46 | C5: =IFERROR( IF(_xlfn.XLOOKUP(A5,Carichi!B:B,Carichi!D:D)="", B5, _xlfn.XLOOKUP(A5,Carichi!B:B,Carichi!D:D) ), B5 ) -> 5.46 | D5: 0 | E5: =D5 +SUMIF(Carichi!B:B,A5,Carichi!C:C)-F5+G5 -> 0 | F5: =SUMIF(Ordini!E:E,TRIM(A5),Ordini!F:F) -> 0 | G5: =SUMIFS(Ordini!N:N,Ordini!E:E,A5,Ordini!M:M,"Reso")+SUMIFS(Ordini!N:N,Ordini!E:E,A5,Ordini!M:M,"RimborsatoReso") -> 0 | H5: 10 | I5: =IFERROR(SUMIFS(Ordini!F:F,Ordini!E:E,A5)/30,1) -> 0 | J5: =IF(I5<=0,"NESSUNA ROTAZIONE","ROT: 1 pz ogni "&ROUND(1/I5,0)&" gg") -> NESSUNA ROTAZIONE | K5: =IF(OR('Prodotti Magazzino'!$I5=0,'Prodotti Magazzino'!$I5=""), "NESSUNA VENDITA", ROUND('Prodotti Magazzino'!$E5/'Prodotti Magazzino'!$I5,0) ) -> NESSUNA VENDITA | L5: =ROUND(IF('Prodotti Magazzino'!$I5<=0,0,'Prodotti Magazzino'!$I5*('Prodotti Magazzino'!$H5+7)),0) -> 0 | M5: =ROUND(MAX(0,(I5*(H5+14))-E5),0) -> 0 | N5: =IF(E5 < I5*H5,"ORDINA SUBITO", IF(E5 < I5*(H5+14),"PREPARA", "OK")) -> OK | O5: ='Prodotti Magazzino'!$E5*'Prodotti Magazzino'!$B5 -> 0
A6: Cuociuova in Acciaio Inox - KD4118 | B6: =9.2+1.62 -> 10.82 | C6: =IFERROR( IF(_xlfn.XLOOKUP(A6,Carichi!B:B,Carichi!D:D)="", B6, _xlfn.XLOOKUP(A6,Carichi!B:B,Carichi!D:D) ), B6 ) -> 10.82 | D6: 7 | E6: =D6 +SUMIF(Carichi!B:B,A6,Carichi!C:C)-F6+G6 -> 0 | F6: =SUMIF(Ordini!E:E,TRIM(A6),Ordini!F:F) -> 7 | G6: =SUMIFS(Ordini!N:N,Ordini!E:E,A6,Ordini!M:M,"Reso")+SUMIFS(Ordini!N:N,Ordini!E:E,A6,Ordini!M:M,"RimborsatoReso") -> 0 | H6: 10 | I6: =IFERROR(SUMIFS(Ordini!F:F,Ordini!E:E,A6)/30,1) -> 0.23333333 | J6: =IF(I6<=0,"NESSUNA ROTAZIONE","ROT: 1 pz ogni "&ROUND(1/I6,0)&" gg") -> ROT: 1 pz ogni 4 gg | K6: =IF(OR('Prodotti Magazzino'!$I6=0,'Prodotti Magazzino'!$I6=""), "NESSUNA VENDITA", ROUND('Prodotti Magazzino'!$E6/'Prodotti Magazzino'!$I6,0) ) -> 0 | L6: =ROUND(IF('Prodotti Magazzino'!$I6<=0,0,'Prodotti Magazzino'!$I6*('Prodotti Magazzino'!$H6+7)),0) -> 4 | M6: =ROUND(MAX(0,(I6*(H6+14))-E6),0) -> 6 | N6: =IF(E6 < I6*H6,"ORDINA SUBITO", IF(E6 < I6*(H6+14),"PREPARA", "OK")) -> ORDINA SUBITO | O6: ='Prodotti Magazzino'!$E6*'Prodotti Magazzino'!$B6 -> 0
A7: Frullatore Elettrico a Immersione - KD4110 | B7: =13.8+4.68 -> 18.48 | C7: =IFERROR( IF(_xlfn.XLOOKUP(A7,Carichi!B:B,Carichi!D:D)="", B7, _xlfn.XLOOKUP(A7,Carichi!B:B,Carichi!D:D) ), B7 ) -> 18.48 | D7: 1 | E7: =D7 +SUMIF(Carichi!B:B,A7,Carichi!C:C)-F7+G7 -> 0 | F7: =SUMIF(Ordini!E:E,TRIM(A7),Ordini!F:F) -> 1 | G7: =SUMIFS(Ordini!N:N,Ordini!E:E,A7,Ordini!M:M,"Reso")+SUMIFS(Ordini!N:N,Ordini!E:E,A7,Ordini!M:M,"RimborsatoReso") -> 0 | H7: 10 | I7: =IFERROR(SUMIFS(Ordini!F:F,Ordini!E:E,A7)/30,1) -> 0.033333333 | J7: =IF(I7<=0,"NESSUNA ROTAZIONE","ROT: 1 pz ogni "&ROUND(1/I7,0)&" gg") -> ROT: 1 pz ogni 30 gg | K7: =IF(OR('Prodotti Magazzino'!$I7=0,'Prodotti Magazzino'!$I7=""), "NESSUNA VENDITA", ROUND('Prodotti Magazzino'!$E7/'Prodotti Magazzino'!$I7,0) ) -> 0 | L7: =ROUND(IF('Prodotti Magazzino'!$I7<=0,0,'Prodotti Magazzino'!$I7*('Prodotti Magazzino'!$H7+7)),0) -> 1 | M7: =ROUND(MAX(0,(I7*(H7+14))-E7),0) -> 1 | N7: =IF(E7 < I7*H7,"ORDINA SUBITO", IF(E7 < I7*(H7+14),"PREPARA", "OK")) -> ORDINA SUBITO | O7: ='Prodotti Magazzino'!$E7*'Prodotti Magazzino'!$B7 -> 0
A8: Avvitatore a Batteria - KD3086 | B8: =17.25+1.62 -> 18.87 | C8: =IFERROR( IF(_xlfn.XLOOKUP(A8,Carichi!B:B,Carichi!D:D)="", B8, _xlfn.XLOOKUP(A8,Carichi!B:B,Carichi!D:D) ), B8 ) -> 18.87 | D8: 0 | E8: =D8 +SUMIF(Carichi!B:B,A8,Carichi!C:C)-F8+G8 -> 0 | F8: =SUMIF(Ordini!E:E,TRIM(A8),Ordini!F:F) -> 0 | G8: =SUMIFS(Ordini!N:N,Ordini!E:E,A8,Ordini!M:M,"Reso")+SUMIFS(Ordini!N:N,Ordini!E:E,A8,Ordini!M:M,"RimborsatoReso") -> 0 | H8: 10 | I8: =IFERROR(SUMIFS(Ordini!F:F,Ordini!E:E,A8)/30,1) -> 0 | J8: =IF(I8<=0,"NESSUNA ROTAZIONE","ROT: 1 pz ogni "&ROUND(1/I8,0)&" gg") -> NESSUNA ROTAZIONE | K8: =IF(OR('Prodotti Magazzino'!$I8=0,'Prodotti Magazzino'!$I8=""), "NESSUNA VENDITA", ROUND('Prodotti Magazzino'!$E8/'Prodotti Magazzino'!$I8,0) ) -> NESSUNA VENDITA | L8: =ROUND(IF('Prodotti Magazzino'!$I8<=0,0,'Prodotti Magazzino'!$I8*('Prodotti Magazzino'!$H8+7)),0) -> 0 | M8: =ROUND(MAX(0,(I8*(H8+14))-E8),0) -> 0 | N8: =IF(E8 < I8*H8,"ORDINA SUBITO", IF(E8 < I8*(H8+14),"PREPARA", "OK")) -> OK | O8: ='Prodotti Magazzino'!$E8*'Prodotti Magazzino'!$B8 -> 0
A9: Kit Sollevatore Mobili - KD3019 | B9: =2.68+1.62 -> 4.3 | C9: =IFERROR( IF(_xlfn.XLOOKUP(A9,Carichi!B:B,Carichi!D:D)="", B9, _xlfn.XLOOKUP(A9,Carichi!B:B,Carichi!D:D) ), B9 ) -> 4.3 | D9: 1 | E9: =D9 +SUMIF(Carichi!B:B,A9,Carichi!C:C)-F9+G9 -> 1 | F9: =SUMIF(Ordini!E:E,TRIM(A9),Ordini!F:F) -> 1 | G9: =SUMIFS(Ordini!N:N,Ordini!E:E,A9,Ordini!M:M,"Reso")+SUMIFS(Ordini!N:N,Ordini!E:E,A9,Ordini!M:M,"RimborsatoReso") -> 1 | H9: 10 | I9: =IFERROR(SUMIFS(Ordini!F:F,Ordini!E:E,A9)/30,1) -> 0.033333333 | J9: =IF(I9<=0,"NESSUNA ROTAZIONE","ROT: 1 pz ogni "&ROUND(1/I9,0)&" gg") -> ROT: 1 pz ogni 30 gg | K9: =IF(OR('Prodotti Magazzino'!$I9=0,'Prodotti Magazzino'!$I9=""), "NESSUNA VENDITA", ROUND('Prodotti Magazzino'!$E9/'Prodotti Magazzino'!$I9,0) ) -> 30 | L9: =ROUND(IF('Prodotti Magazzino'!$I9<=0,0,'Prodotti Magazzino'!$I9*('Prodotti Magazzino'!$H9+7)),0) -> 1 | M9: =ROUND(MAX(0,(I9*(H9+14))-E9),0) -> 0 | N9: =IF(E9 < I9*H9,"ORDINA SUBITO", IF(E9 < I9*(H9+14),"PREPARA", "OK")) -> OK | O9: ='Prodotti Magazzino'!$E9*'Prodotti Magazzino'!$B9 -> 4.3
A10: Irroratore a pressione - KD2033 | B10: =4.79+1.62 -> 6.41 | C10: =IFERROR( IF(_xlfn.XLOOKUP(A10,Carichi!B:B,Carichi!D:D)="", B10, _xlfn.XLOOKUP(A10,Carichi!B:B,Carichi!D:D) ), B10 ) -> 6.9 | D10: 12 | E10: =D10 +SUMIF(Carichi!B:B,A10,Carichi!C:C)-F10+G10 -> 2 | F10: =SUMIF(Ordini!E:E,TRIM(A10),Ordini!F:F) -> 46 | G10: =SUMIFS(Ordini!N:N,Ordini!E:E,A10,Ordini!M:M,"Reso")+SUMIFS(Ordini!N:N,Ordini!E:E,A10,Ordini!M:M,"RimborsatoReso") -> 1 | H10: 10 | I10: =IFERROR(SUMIFS(Ordini!F:F,Ordini!E:E,A10)/30,1) -> 1.5333333 | J10: =IF(I10<=0,"NESSUNA ROTAZIONE","ROT: 1 pz ogni "&ROUND(1/I10,0)&" gg") -> ROT: 1 pz ogni 1 gg | K10: =IF(OR('Prodotti Magazzino'!$I10=0,'Prodotti Magazzino'!$I10=""), "NESSUNA VENDITA", ROUND('Prodotti Magazzino'!$E10/'Prodotti Magazzino'!$I10,0) ) -> 1 | L10: =ROUND(IF('Prodotti Magazzino'!$I10<=0,0,'Prodotti Magazzino'!$I10*('Prodotti Magazzino'!$H10+7)),0) -> 26 | M10: =ROUND(MAX(0,(I10*(H10+14))-E10),0) -> 35 | N10: =IF(E10 < I10*H10,"ORDINA SUBITO", IF(E10 < I10*(H10+14),"PREPARA", "OK")) -> ORDINA SUBITO | O10: ='Prodotti Magazzino'!$E10*'Prodotti Magazzino'!$B10 -> 12.82
A11: Irroratrice a batteria - KD2032 | B11: =19.16+1.62 -> 20.78 | C11: =IFERROR( IF(_xlfn.XLOOKUP(A11,Carichi!B:B,Carichi!D:D)="", B11, _xlfn.XLOOKUP(A11,Carichi!B:B,Carichi!D:D) ), B11 ) -> 20.78 | D11: 0 | E11: =D11 +SUMIF(Carichi!B:B,A11,Carichi!C:C)-F11+G11 -> 0 | F11: =SUMIF(Ordini!E:E,TRIM(A11),Ordini!F:F) -> 0 | G11: =SUMIFS(Ordini!N:N,Ordini!E:E,A11,Ordini!M:M,"Reso")+SUMIFS(Ordini!N:N,Ordini!E:E,A11,Ordini!M:M,"RimborsatoReso") -> 0 | H11: 10 | I11: =IFERROR(SUMIFS(Ordini!F:F,Ordini!E:E,A11)/30,1) -> 0 | J11: =IF(I11<=0,"NESSUNA ROTAZIONE","ROT: 1 pz ogni "&ROUND(1/I11,0)&" gg") -> NESSUNA ROTAZIONE | K11: =IF(OR('Prodotti Magazzino'!$I11=0,'Prodotti Magazzino'!$I11=""), "NESSUNA VENDITA", ROUND('Prodotti Magazzino'!$E11/'Prodotti Magazzino'!$I11,0) ) -> NESSUNA VENDITA | L11: =ROUND(IF('Prodotti Magazzino'!$I11<=0,0,'Prodotti Magazzino'!$I11*('Prodotti Magazzino'!$H11+7)),0) -> 0 | M11: =ROUND(MAX(0,(I11*(H11+14))-E11),0) -> 0 | N11: =IF(E11 < I11*H11,"ORDINA SUBITO", IF(E11 < I11*(H11+14),"PREPARA", "OK")) -> OK | O11: ='Prodotti Magazzino'!$E11*'Prodotti Magazzino'!$B11 -> 0
A12: Levigatrice Eccentrica - KD1684 | B12: =12.46+1.62+4.68 -> 18.76 | C12: =IFERROR( IF(_xlfn.XLOOKUP(A12,Carichi!B:B,Carichi!D:D)="", B12, _xlfn.XLOOKUP(A12,Carichi!B:B,Carichi!D:D) ), B12 ) -> 18.76 | D12: 0 | E12: =D12 +SUMIF(Carichi!B:B,A12,Carichi!C:C)-F12+G12 -> 0 | F12: =SUMIF(Ordini!E:E,TRIM(A12),Ordini!F:F) -> 0 | G12: =SUMIFS(Ordini!N:N,Ordini!E:E,A12,Ordini!M:M,"Reso")+SUMIFS(Ordini!N:N,Ordini!E:E,A12,Ordini!M:M,"RimborsatoReso") -> 0 | H12: 10 | I12: =IFERROR(SUMIFS(Ordini!F:F,Ordini!E:E,A12)/30,1) -> 0 | J12: =IF(I12<=0,"NESSUNA ROTAZIONE","ROT: 1 pz ogni "&ROUND(1/I12,0)&" gg") -> NESSUNA ROTAZIONE | K12: =IF(OR('Prodotti Magazzino'!$I12=0,'Prodotti Magazzino'!$I12=""), "NESSUNA VENDITA", ROUND('Prodotti Magazzino'!$E12/'Prodotti Magazzino'!$I12,0) ) -> NESSUNA VENDITA | L12: =ROUND(IF('Prodotti Magazzino'!$I12<=0,0,'Prodotti Magazzino'!$I12*('Prodotti Magazzino'!$H12+7)),0) -> 0 | M12: =ROUND(MAX(0,(I12*(H12+14))-E12),0) -> 0 | N12: =IF(E12 < I12*H12,"ORDINA SUBITO", IF(E12 < I12*(H12+14),"PREPARA", "OK")) -> OK | O12: ='Prodotti Magazzino'!$E12*'Prodotti Magazzino'!$B12 -> 0
A13: Utensile Multifunzione Oscillante - KD1672 | B13: =20.5+1.62 -> 22.12 | C13: =IFERROR( IF(_xlfn.XLOOKUP(A13,Carichi!B:B,Carichi!D:D)="", B13, _xlfn.XLOOKUP(A13,Carichi!B:B,Carichi!D:D) ), B13 ) -> 22.12 | D13: 0 | E13: =D13 +SUMIF(Carichi!B:B,A13,Carichi!C:C)-F13+G13 -> 0 | F13: =SUMIF(Ordini!E:E,TRIM(A13),Ordini!F:F) -> 0 | G13: =SUMIFS(Ordini!N:N,Ordini!E:E,A13,Ordini!M:M,"Reso")+SUMIFS(Ordini!N:N,Ordini!E:E,A13,Ordini!M:M,"RimborsatoReso") -> 0 | H13: 10 | I13: =IFERROR(SUMIFS(Ordini!F:F,Ordini!E:E,A13)/30,1) -> 0 | J13: =IF(I13<=0,"NESSUNA ROTAZIONE","ROT: 1 pz ogni "&ROUND(1/I13,0)&" gg") -> NESSUNA ROTAZIONE | K13: =IF(OR('Prodotti Magazzino'!$I13=0,'Prodotti Magazzino'!$I13=""), "NESSUNA VENDITA", ROUND('Prodotti Magazzino'!$E13/'Prodotti Magazzino'!$I13,0) ) -> NESSUNA VENDITA | L13: =ROUND(IF('Prodotti Magazzino'!$I13<=0,0,'Prodotti Magazzino'!$I13*('Prodotti Magazzino'!$H13+7)),0) -> 0 | M13: =ROUND(MAX(0,(I13*(H13+14))-E13),0) -> 0 | N13: =IF(E13 < I13*H13,"ORDINA SUBITO", IF(E13 < I13*(H13+14),"PREPARA", "OK")) -> OK | O13: ='Prodotti Magazzino'!$E13*'Prodotti Magazzino'!$B13 -> 0
A14: Manometro - KD1365 | B14: =8.82+1.62 -> 10.44 | C14: =IFERROR( IF(_xlfn.XLOOKUP(A14,Carichi!B:B,Carichi!D:D)="", B14, _xlfn.XLOOKUP(A14,Carichi!B:B,Carichi!D:D) ), B14 ) -> 10.44 | D14: 9 | E14: =D14 +SUMIF(Carichi!B:B,A14,Carichi!C:C)-F14+G14 -> 1 | F14: =SUMIF(Ordini!E:E,TRIM(A14),Ordini!F:F) -> 9 | G14: =SUMIFS(Ordini!N:N,Ordini!E:E,A14,Ordini!M:M,"Reso")+SUMIFS(Ordini!N:N,Ordini!E:E,A14,Ordini!M:M,"RimborsatoReso") -> 1 | H14: 10 | I14: =IFERROR(SUMIFS(Ordini!F:F,Ordini!E:E,A14)/30,1) -> 0.3 | J14: =IF(I14<=0,"NESSUNA ROTAZIONE","ROT: 1 pz ogni "&ROUND(1/I14,0)&" gg") -> ROT: 1 pz ogni 3 gg | K14: =IF(OR('Prodotti Magazzino'!$I14=0,'Prodotti Magazzino'!$I14=""), "NESSUNA VENDITA", ROUND('Prodotti Magazzino'!$E14/'Prodotti Magazzino'!$I14,0) ) -> 3 | L14: =ROUND(IF('Prodotti Magazzino'!$I14<=0,0,'Prodotti Magazzino'!$I14*('Prodotti Magazzino'!$H14+7)),0) -> 5 | M14: =ROUND(MAX(0,(I14*(H14+14))-E14),0) -> 6 | N14: =IF(E14 < I14*H14,"ORDINA SUBITO", IF(E14 < I14*(H14+14),"PREPARA", "OK")) -> ORDINA SUBITO | O14: ='Prodotti Magazzino'!$E14*'Prodotti Magazzino'!$B14 -> 10.44
A15: Multimetro Digitale - KD11297 | B15: =5.36+1.62 -> 6.98 | C15: =IFERROR( IF(_xlfn.XLOOKUP(A15,Carichi!B:B,Carichi!D:D)="", B15, _xlfn.XLOOKUP(A15,Carichi!B:B,Carichi!D:D) ), B15 ) -> 6.98 | D15: 0 | E15: =D15 +SUMIF(Carichi!B:B,A15,Carichi!C:C)-F15+G15 -> 0 | F15: =SUMIF(Ordini!E:E,TRIM(A15),Ordini!F:F) -> 0 | G15: =SUMIFS(Ordini!N:N,Ordini!E:E,A15,Ordini!M:M,"Reso")+SUMIFS(Ordini!N:N,Ordini!E:E,A15,Ordini!M:M,"RimborsatoReso") -> 0 | H15: 10 | I15: =IFERROR(SUMIFS(Ordini!F:F,Ordini!E:E,A15)/30,1) -> 0 | J15: =IF(I15<=0,"NESSUNA ROTAZIONE","ROT: 1 pz ogni "&ROUND(1/I15,0)&" gg") -> NESSUNA ROTAZIONE | K15: =IF(OR('Prodotti Magazzino'!$I15=0,'Prodotti Magazzino'!$I15=""), "NESSUNA VENDITA", ROUND('Prodotti Magazzino'!$E15/'Prodotti Magazzino'!$I15,0) ) -> NESSUNA VENDITA | L15: =ROUND(IF('Prodotti Magazzino'!$I15<=0,0,'Prodotti Magazzino'!$I15*('Prodotti Magazzino'!$H15+7)),0) -> 0 | M15: =ROUND(MAX(0,(I15*(H15+14))-E15),0) -> 0 | N15: =IF(E15 < I15*H15,"ORDINA SUBITO", IF(E15 < I15*(H15+14),"PREPARA", "OK")) -> OK | O15: ='Prodotti Magazzino'!$E15*'Prodotti Magazzino'!$B15 -> 0
A16: Chiavi Inglesi Combinate - KD10923 | B16: =5+1.62 -> 6.62 | C16: =IFERROR( IF(_xlfn.XLOOKUP(A16,Carichi!B:B,Carichi!D:D)="", B16, _xlfn.XLOOKUP(A16,Carichi!B:B,Carichi!D:D) ), B16 ) -> 6.62 | D16: 22 | E16: =D16 +SUMIF(Carichi!B:B,A16,Carichi!C:C)-F16+G16 -> 0 | F16: =SUMIF(Ordini!E:E,TRIM(A16),Ordini!F:F) -> 22 | G16: =SUMIFS(Ordini!N:N,Ordini!E:E,A16,Ordini!M:M,"Reso")+SUMIFS(Ordini!N:N,Ordini!E:E,A16,Ordini!M:M,"RimborsatoReso") -> 0 | H16: 10 | I16: =IFERROR(SUMIFS(Ordini!F:F,Ordini!E:E,A16)/30,1) -> 0.73333333 | J16: =IF(I16<=0,"NESSUNA ROTAZIONE","ROT: 1 pz ogni "&ROUND(1/I16,0)&" gg") -> ROT: 1 pz ogni 1 gg | K16: =IF(OR('Prodotti Magazzino'!$I16=0,'Prodotti Magazzino'!$I16=""), "NESSUNA VENDITA", ROUND('Prodotti Magazzino'!$E16/'Prodotti Magazzino'!$I16,0) ) -> 0 | L16: =ROUND(IF('Prodotti Magazzino'!$I16<=0,0,'Prodotti Magazzino'!$I16*('Prodotti Magazzino'!$H16+7)),0) -> 12 | M16: =ROUND(MAX(0,(I16*(H16+14))-E16),0) -> 18 | N16: =IF(E16 < I16*H16,"ORDINA SUBITO", IF(E16 < I16*(H16+14),"PREPARA", "OK")) -> ORDINA SUBITO | O16: ='Prodotti Magazzino'!$E16*'Prodotti Magazzino'!$B16 -> 0
A17: Set Attrezzi 180 Pezzi - KD10838 | B17: =11.11+1.62 -> 12.73 | C17: =IFERROR( IF(_xlfn.XLOOKUP(A17,Carichi!B:B,Carichi!D:D)="", B17, _xlfn.XLOOKUP(A17,Carichi!B:B,Carichi!D:D) ), B17 ) -> 12.73 | D17: 0 | E17: =D17 +SUMIF(Carichi!B:B,A17,Carichi!C:C)-F17+G17 -> 0 | F17: =SUMIF(Ordini!E:E,TRIM(A17),Ordini!F:F) -> 0 | G17: =SUMIFS(Ordini!N:N,Ordini!E:E,A17,Ordini!M:M,"Reso")+SUMIFS(Ordini!N:N,Ordini!E:E,A17,Ordini!M:M,"RimborsatoReso") -> 0 | H17: 10 | I17: =IFERROR(SUMIFS(Ordini!F:F,Ordini!E:E,A17)/30,1) -> 0 | J17: =IF(I17<=0,"NESSUNA ROTAZIONE","ROT: 1 pz ogni "&ROUND(1/I17,0)&" gg") -> NESSUNA ROTAZIONE | K17: =IF(OR('Prodotti Magazzino'!$I17=0,'Prodotti Magazzino'!$I17=""), "NESSUNA VENDITA", ROUND('Prodotti Magazzino'!$E17/'Prodotti Magazzino'!$I17,0) ) -> NESSUNA VENDITA | L17: =ROUND(IF('Prodotti Magazzino'!$I17<=0,0,'Prodotti Magazzino'!$I17*('Prodotti Magazzino'!$H17+7)),0) -> 0 | M17: =ROUND(MAX(0,(I17*(H17+14))-E17),0) -> 0 | N17: =IF(E17 < I17*H17,"ORDINA SUBITO", IF(E17 < I17*(H17+14),"PREPARA", "OK")) -> OK | O17: ='Prodotti Magazzino'!$E17*'Prodotti Magazzino'!$B17 -> 0
A18: Panca da Giardino - KD10634 | B18: =6.9+1.62 -> 8.52 | C18: =IFERROR( IF(_xlfn.XLOOKUP(A18,Carichi!B:B,Carichi!D:D)="", B18, _xlfn.XLOOKUP(A18,Carichi!B:B,Carichi!D:D) ), B18 ) -> 8.52 | D18: 0 | E18: =D18 +SUMIF(Carichi!B:B,A18,Carichi!C:C)-F18+G18 -> 0 | F18: =SUMIF(Ordini!E:E,TRIM(A18),Ordini!F:F) -> 0 | G18: =SUMIFS(Ordini!N:N,Ordini!E:E,A18,Ordini!M:M,"Reso")+SUMIFS(Ordini!N:N,Ordini!E:E,A18,Ordini!M:M,"RimborsatoReso") -> 0 | H18: 10 | I18: =IFERROR(SUMIFS(Ordini!F:F,Ordini!E:E,A18)/30,1) -> 0 | J18: =IF(I18<=0,"NESSUNA ROTAZIONE","ROT: 1 pz ogni "&ROUND(1/I18,0)&" gg") -> NESSUNA ROTAZIONE | K18: =IF(OR('Prodotti Magazzino'!$I18=0,'Prodotti Magazzino'!$I18=""), "NESSUNA VENDITA", ROUND('Prodotti Magazzino'!$E18/'Prodotti Magazzino'!$I18,0) ) -> NESSUNA VENDITA | L18: =ROUND(IF('Prodotti Magazzino'!$I18<=0,0,'Prodotti Magazzino'!$I18*('Prodotti Magazzino'!$H18+7)),0) -> 0 | M18: =ROUND(MAX(0,(I18*(H18+14))-E18),0) -> 0 | N18: =IF(E18 < I18*H18,"ORDINA SUBITO", IF(E18 < I18*(H18+14),"PREPARA", "OK")) -> OK | O18: ='Prodotti Magazzino'!$E18*'Prodotti Magazzino'!$B18 -> 0
A19: Motosega a scoppio 52 CC - KD10614 | B19: =31.62+1.62 -> 33.24 | C19: =IFERROR( IF(_xlfn.XLOOKUP(A19,Carichi!B:B,Carichi!D:D)="", B19, _xlfn.XLOOKUP(A19,Carichi!B:B,Carichi!D:D) ), B19 ) -> 33.24 | D19: 0 | E19: =D19 +SUMIF(Carichi!B:B,A19,Carichi!C:C)-F19+G19 -> 0 | F19: =SUMIF(Ordini!E:E,TRIM(A19),Ordini!F:F) -> 0 | G19: =SUMIFS(Ordini!N:N,Ordini!E:E,A19,Ordini!M:M,"Reso")+SUMIFS(Ordini!N:N,Ordini!E:E,A19,Ordini!M:M,"RimborsatoReso") -> 0 | H19: 10 | I19: =IFERROR(SUMIFS(Ordini!F:F,Ordini!E:E,A19)/30,1) -> 0 | J19: =IF(I19<=0,"NESSUNA ROTAZIONE","ROT: 1 pz ogni "&ROUND(1/I19,0)&" gg") -> NESSUNA ROTAZIONE | K19: =IF(OR('Prodotti Magazzino'!$I19=0,'Prodotti Magazzino'!$I19=""), "NESSUNA VENDITA", ROUND('Prodotti Magazzino'!$E19/'Prodotti Magazzino'!$I19,0) ) -> NESSUNA VENDITA | L19: =ROUND(IF('Prodotti Magazzino'!$I19<=0,0,'Prodotti Magazzino'!$I19*('Prodotti Magazzino'!$H19+7)),0) -> 0 | M19: =ROUND(MAX(0,(I19*(H19+14))-E19),0) -> 0 | N19: =IF(E19 < I19*H19,"ORDINA SUBITO", IF(E19 < I19*(H19+14),"PREPARA", "OK")) -> OK | O19: ='Prodotti Magazzino'!$E19*'Prodotti Magazzino'!$B19 -> 0
A20: Motosega a Scoppio 58cc - KD10613 | B20: =38.14+1.62 -> 39.76 | C20: =IFERROR( IF(_xlfn.XLOOKUP(A20,Carichi!B:B,Carichi!D:D)="", B20, _xlfn.XLOOKUP(A20,Carichi!B:B,Carichi!D:D) ), B20 ) -> 42.63 | D20: 25 | E20: =D20 +SUMIF(Carichi!B:B,A20,Carichi!C:C)-F20+G20 -> -1 | F20: =SUMIF(Ordini!E:E,TRIM(A20),Ordini!F:F) -> 66 | G20: =SUMIFS(Ordini!N:N,Ordini!E:E,A20,Ordini!M:M,"Reso")+SUMIFS(Ordini!N:N,Ordini!E:E,A20,Ordini!M:M,"RimborsatoReso") -> 0 | H20: 10 | I20: =IFERROR(SUMIFS(Ordini!F:F,Ordini!E:E,A20)/30,1) -> 2.2 | J20: =IF(I20<=0,"NESSUNA ROTAZIONE","ROT: 1 pz ogni "&ROUND(1/I20,0)&" gg") -> ROT: 1 pz ogni 0 gg | K20: =IF(OR('Prodotti Magazzino'!$I20=0,'Prodotti Magazzino'!$I20=""), "NESSUNA VENDITA", ROUND('Prodotti Magazzino'!$E20/'Prodotti Magazzino'!$I20,0) ) -> 0 | L20: =ROUND(IF('Prodotti Magazzino'!$I20<=0,0,'Prodotti Magazzino'!$I20*('Prodotti Magazzino'!$H20+7)),0) -> 37 | M20: =ROUND(MAX(0,(I20*(H20+14))-E20),0) -> 54 | N20: =IF(E20 < I20*H20,"ORDINA SUBITO", IF(E20 < I20*(H20+14),"PREPARA", "OK")) -> ORDINA SUBITO | O20: ='Prodotti Magazzino'!$E20*'Prodotti Magazzino'!$B20 -> -39.76 | P20: 8 | Q20: =57*27*27 -> 41553
A21: Set chiavi a bussola 219pz - KD10470 | B21: =37.75+1.62 -> 39.37 | C21: =IFERROR( IF(_xlfn.XLOOKUP(A21,Carichi!B:B,Carichi!D:D)="", B21, _xlfn.XLOOKUP(A21,Carichi!B:B,Carichi!D:D) ), B21 ) -> 39.37 | D21: 0 | E21: =D21 +SUMIF(Carichi!B:B,A21,Carichi!C:C)-F21+G21 -> 0 | F21: =SUMIF(Ordini!E:E,TRIM(A21),Ordini!F:F) -> 0 | G21: =SUMIFS(Ordini!N:N,Ordini!E:E,A21,Ordini!M:M,"Reso")+SUMIFS(Ordini!N:N,Ordini!E:E,A21,Ordini!M:M,"RimborsatoReso") -> 0 | H21: 10 | I21: =IFERROR(SUMIFS(Ordini!F:F,Ordini!E:E,A21)/30,1) -> 0 | J21: =IF(I21<=0,"NESSUNA ROTAZIONE","ROT: 1 pz ogni "&ROUND(1/I21,0)&" gg") -> NESSUNA ROTAZIONE | K21: =IF(OR('Prodotti Magazzino'!$I21=0,'Prodotti Magazzino'!$I21=""), "NESSUNA VENDITA", ROUND('Prodotti Magazzino'!$E21/'Prodotti Magazzino'!$I21,0) ) -> NESSUNA VENDITA | L21: =ROUND(IF('Prodotti Magazzino'!$I21<=0,0,'Prodotti Magazzino'!$I21*('Prodotti Magazzino'!$H21+7)),0) -> 0 | M21: =ROUND(MAX(0,(I21*(H21+14))-E21),0) -> 0 | N21: =IF(E21 < I21*H21,"ORDINA SUBITO", IF(E21 < I21*(H21+14),"PREPARA", "OK")) -> OK | O21: ='Prodotti Magazzino'!$E21*'Prodotti Magazzino'!$B21 -> 0
A22: Calibro digitale - KD10073 | B22: =2.11+1.62 -> 3.73 | C22: =IFERROR( IF(_xlfn.XLOOKUP(A22,Carichi!B:B,Carichi!D:D)="", B22, _xlfn.XLOOKUP(A22,Carichi!B:B,Carichi!D:D) ), B22 ) -> 3.73 | D22: 0 | E22: =D22 +SUMIF(Carichi!B:B,A22,Carichi!C:C)-F22+G22 -> 0 | F22: =SUMIF(Ordini!E:E,TRIM(A22),Ordini!F:F) -> 0 | G22: =SUMIFS(Ordini!N:N,Ordini!E:E,A22,Ordini!M:M,"Reso")+SUMIFS(Ordini!N:N,Ordini!E:E,A22,Ordini!M:M,"RimborsatoReso") -> 0 | H22: 10 | I22: =IFERROR(SUMIFS(Ordini!F:F,Ordini!E:E,A22)/30,1) -> 0 | J22: =IF(I22<=0,"NESSUNA ROTAZIONE","ROT: 1 pz ogni "&ROUND(1/I22,0)&" gg") -> NESSUNA ROTAZIONE | K22: =IF(OR('Prodotti Magazzino'!$I22=0,'Prodotti Magazzino'!$I22=""), "NESSUNA VENDITA", ROUND('Prodotti Magazzino'!$E22/'Prodotti Magazzino'!$I22,0) ) -> NESSUNA VENDITA | L22: =ROUND(IF('Prodotti Magazzino'!$I22<=0,0,'Prodotti Magazzino'!$I22*('Prodotti Magazzino'!$H22+7)),0) -> 0 | M22: =ROUND(MAX(0,(I22*(H22+14))-E22),0) -> 0 | N22: =IF(E22 < I22*H22,"ORDINA SUBITO", IF(E22 < I22*(H22+14),"PREPARA", "OK")) -> OK | O22: ='Prodotti Magazzino'!$E22*'Prodotti Magazzino'!$B22 -> 0
A23: Motore A Scoppio 210cc - KD1825 | B23: =40.37+2.26 -> 42.63 | C23: =IFERROR( IF(_xlfn.XLOOKUP(A23,Carichi!B:B,Carichi!D:D)="", B23, _xlfn.XLOOKUP(A23,Carichi!B:B,Carichi!D:D) ), B23 ) -> 43.59 | D23: 6 | E23: =D23 +SUMIF(Carichi!B:B,A23,Carichi!C:C)-F23+G23 -> 0 | F23: =SUMIF(Ordini!E:E,TRIM(A23),Ordini!F:F) -> 13 | G23: =SUMIFS(Ordini!N:N,Ordini!E:E,A23,Ordini!M:M,"Reso")+SUMIFS(Ordini!N:N,Ordini!E:E,A23,Ordini!M:M,"RimborsatoReso") -> 1 | H23: 10 | I23: =IFERROR(SUMIFS(Ordini!F:F,Ordini!E:E,A23)/30,1) -> 0.43333333 | J23: =IF(I23<=0,"NESSUNA ROTAZIONE","ROT: 1 pz ogni "&ROUND(1/I23,0)&" gg") -> ROT: 1 pz ogni 2 gg | K23: =IF(OR('Prodotti Magazzino'!$I23=0,'Prodotti Magazzino'!$I23=""), "NESSUNA VENDITA", ROUND('Prodotti Magazzino'!$E23/'Prodotti Magazzino'!$I23,0) ) -> 0 | L23: =ROUND(IF('Prodotti Magazzino'!$I23<=0,0,'Prodotti Magazzino'!$I23*('Prodotti Magazzino'!$H23+7)),0) -> 7 | M23: =ROUND(MAX(0,(I23*(H23+14))-E23),0) -> 10 | N23: =IF(E23 < I23*H23,"ORDINA SUBITO", IF(E23 < I23*(H23+14),"PREPARA", "OK")) -> ORDINA SUBITO | O23: ='Prodotti Magazzino'!$E23*'Prodotti Magazzino'!$B23 -> 0
A24: Lampione Solare - KD3481 | B24: =10.58+2.26 -> 12.84 | C24: =IFERROR( IF(_xlfn.XLOOKUP(A24,Carichi!B:B,Carichi!D:D)="", B24, _xlfn.XLOOKUP(A24,Carichi!B:B,Carichi!D:D) ), B24 ) -> 12.84 | D24: 0 | E24: =D24 +SUMIF(Carichi!B:B,A24,Carichi!C:C)-F24+G24 -> 0 | F24: =SUMIF(Ordini!E:E,TRIM(A24),Ordini!F:F) -> 0 | G24: =SUMIFS(Ordini!N:N,Ordini!E:E,A24,Ordini!M:M,"Reso")+SUMIFS(Ordini!N:N,Ordini!E:E,A24,Ordini!M:M,"RimborsatoReso") -> 0 | H24: 10 | I24: =IFERROR(SUMIFS(Ordini!F:F,Ordini!E:E,A24)/30,1) -> 0 | J24: =IF(I24<=0,"NESSUNA ROTAZIONE","ROT: 1 pz ogni "&ROUND(1/I24,0)&" gg") -> NESSUNA ROTAZIONE | K24: =IF(OR('Prodotti Magazzino'!$I24=0,'Prodotti Magazzino'!$I24=""), "NESSUNA VENDITA", ROUND('Prodotti Magazzino'!$E24/'Prodotti Magazzino'!$I24,0) ) -> NESSUNA VENDITA | L24: =ROUND(IF('Prodotti Magazzino'!$I24<=0,0,'Prodotti Magazzino'!$I24*('Prodotti Magazzino'!$H24+7)),0) -> 0 | M24: =ROUND(MAX(0,(I24*(H24+14))-E24),0) -> 0 | N24: =IF(E24 < I24*H24,"ORDINA SUBITO", IF(E24 < I24*(H24+14),"PREPARA", "OK")) -> OK | O24: ='Prodotti Magazzino'!$E24*'Prodotti Magazzino'!$B24 -> 0
A25: Piastra induzione - KD4167 | B25: =31.28+2.5 -> 33.78 | C25: =IFERROR( IF(_xlfn.XLOOKUP(A25,Carichi!B:B,Carichi!D:D)="", B25, _xlfn.XLOOKUP(A25,Carichi!B:B,Carichi!D:D) ), B25 ) -> 33.78 | D25: 15 | E25: =D25 +SUMIF(Carichi!B:B,A25,Carichi!C:C)-F25+G25 -> 0 | F25: =SUMIF(Ordini!E:E,TRIM(A25),Ordini!F:F) -> 15 | G25: =SUMIFS(Ordini!N:N,Ordini!E:E,A25,Ordini!M:M,"Reso")+SUMIFS(Ordini!N:N,Ordini!E:E,A25,Ordini!M:M,"RimborsatoReso") -> 0 | H25: 10 | I25: =IFERROR(SUMIFS(Ordini!F:F,Ordini!E:E,A25)/30,1) -> 0.5 | J25: =IF(I25<=0,"NESSUNA ROTAZIONE","ROT: 1 pz ogni "&ROUND(1/I25,0)&" gg") -> ROT: 1 pz ogni 2 gg | K25: =IF(OR('Prodotti Magazzino'!$I25=0,'Prodotti Magazzino'!$I25=""), "NESSUNA VENDITA", ROUND('Prodotti Magazzino'!$E25/'Prodotti Magazzino'!$I25,0) ) -> 0 | L25: =ROUND(IF('Prodotti Magazzino'!$I25<=0,0,'Prodotti Magazzino'!$I25*('Prodotti Magazzino'!$H25+7)),0) -> 9 | M25: =ROUND(MAX(0,(I25*(H25+14))-E25),0) -> 12 | N25: =IF(E25 < I25*H25,"ORDINA SUBITO", IF(E25 < I25*(H25+14),"PREPARA", "OK")) -> ORDINA SUBITO | O25: ='Prodotti Magazzino'!$E25*'Prodotti Magazzino'!$B25 -> 0
A26: Frullatore Elettrico a Immersione - KD4181 | B26: =17.38+2.5 -> 19.88 | C26: =IFERROR( IF(_xlfn.XLOOKUP(A26,Carichi!B:B,Carichi!D:D)="", B26, _xlfn.XLOOKUP(A26,Carichi!B:B,Carichi!D:D) ), B26 ) -> 19.88 | D26: 0 | E26: =D26 +SUMIF(Carichi!B:B,A26,Carichi!C:C)-F26+G26 -> 0 | F26: =SUMIF(Ordini!E:E,TRIM(A26),Ordini!F:F) -> 0 | G26: =SUMIFS(Ordini!N:N,Ordini!E:E,A26,Ordini!M:M,"Reso")+SUMIFS(Ordini!N:N,Ordini!E:E,A26,Ordini!M:M,"RimborsatoReso") -> 0 | H26: 10 | I26: =IFERROR(SUMIFS(Ordini!F:F,Ordini!E:E,A26)/30,1) -> 0 | J26: =IF(I26<=0,"NESSUNA ROTAZIONE","ROT: 1 pz ogni "&ROUND(1/I26,0)&" gg") -> NESSUNA ROTAZIONE | K26: =IF(OR('Prodotti Magazzino'!$I26=0,'Prodotti Magazzino'!$I26=""), "NESSUNA VENDITA", ROUND('Prodotti Magazzino'!$E26/'Prodotti Magazzino'!$I26,0) ) -> NESSUNA VENDITA | L26: =ROUND(IF('Prodotti Magazzino'!$I26<=0,0,'Prodotti Magazzino'!$I26*('Prodotti Magazzino'!$H26+7)),0) -> 0 | M26: =ROUND(MAX(0,(I26*(H26+14))-E26),0) -> 0 | N26: =IF(E26 < I26*H26,"ORDINA SUBITO", IF(E26 < I26*(H26+14),"PREPARA", "OK")) -> OK | O26: ='Prodotti Magazzino'!$E26*'Prodotti Magazzino'!$B26 -> 0
A27: Crick auto 2,5 T - KD1362 | B27: =20.47+2.5 -> 22.97 | C27: =IFERROR( IF(_xlfn.XLOOKUP(A27,Carichi!B:B,Carichi!D:D)="", B27, _xlfn.XLOOKUP(A27,Carichi!B:B,Carichi!D:D) ), B27 ) -> 22.97 | D27: 0 | E27: =D27 +SUMIF(Carichi!B:B,A27,Carichi!C:C)-F27+G27 -> 0 | F27: =SUMIF(Ordini!E:E,TRIM(A27),Ordini!F:F) -> 0 | G27: =SUMIFS(Ordini!N:N,Ordini!E:E,A27,Ordini!M:M,"Reso")+SUMIFS(Ordini!N:N,Ordini!E:E,A27,Ordini!M:M,"RimborsatoReso") -> 0 | H27: 10 | I27: =IFERROR(SUMIFS(Ordini!F:F,Ordini!E:E,A27)/30,1) -> 0 | J27: =IF(I27<=0,"NESSUNA ROTAZIONE","ROT: 1 pz ogni "&ROUND(1/I27,0)&" gg") -> NESSUNA ROTAZIONE | K27: =IF(OR('Prodotti Magazzino'!$I27=0,'Prodotti Magazzino'!$I27=""), "NESSUNA VENDITA", ROUND('Prodotti Magazzino'!$E27/'Prodotti Magazzino'!$I27,0) ) -> NESSUNA VENDITA | L27: =ROUND(IF('Prodotti Magazzino'!$I27<=0,0,'Prodotti Magazzino'!$I27*('Prodotti Magazzino'!$H27+7)),0) -> 0 | M27: =ROUND(MAX(0,(I27*(H27+14))-E27),0) -> 0 | N27: =IF(E27 < I27*H27,"ORDINA SUBITO", IF(E27 < I27*(H27+14),"PREPARA", "OK")) -> OK | O27: ='Prodotti Magazzino'!$E27*'Prodotti Magazzino'!$B27 -> 0
A28: Cavalletto universale per moto - KD340 | B28: =12.55+2.5 -> 15.05 | C28: =IFERROR( IF(_xlfn.XLOOKUP(A28,Carichi!B:B,Carichi!D:D)="", B28, _xlfn.XLOOKUP(A28,Carichi!B:B,Carichi!D:D) ), B28 ) -> 15.05 | D28: 1 | E28: =D28 +SUMIF(Carichi!B:B,A28,Carichi!C:C)-F28+G28 -> 0 | F28: =SUMIF(Ordini!E:E,TRIM(A28),Ordini!F:F) -> 1 | G28: =SUMIFS(Ordini!N:N,Ordini!E:E,A28,Ordini!M:M,"Reso")+SUMIFS(Ordini!N:N,Ordini!E:E,A28,Ordini!M:M,"RimborsatoReso") -> 0 | H28: 10 | I28: =IFERROR(SUMIFS(Ordini!F:F,Ordini!E:E,A28)/30,1) -> 0.033333333 | J28: =IF(I28<=0,"NESSUNA ROTAZIONE","ROT: 1 pz ogni "&ROUND(1/I28,0)&" gg") -> ROT: 1 pz ogni 30 gg | K28: =IF(OR('Prodotti Magazzino'!$I28=0,'Prodotti Magazzino'!$I28=""), "NESSUNA VENDITA", ROUND('Prodotti Magazzino'!$E28/'Prodotti Magazzino'!$I28,0) ) -> 0 | L28: =ROUND(IF('Prodotti Magazzino'!$I28<=0,0,'Prodotti Magazzino'!$I28*('Prodotti Magazzino'!$H28+7)),0) -> 1 | M28: =ROUND(MAX(0,(I28*(H28+14))-E28),0) -> 1 | N28: =IF(E28 < I28*H28,"ORDINA SUBITO", IF(E28 < I28*(H28+14),"PREPARA", "OK")) -> ORDINA SUBITO | O28: ='Prodotti Magazzino'!$E28*'Prodotti Magazzino'!$B28 -> 0
A29: Microonde 30L - KD4111 | B29: =36.11+2.5 -> 38.61 | C29: =IFERROR( IF(_xlfn.XLOOKUP(A29,Carichi!B:B,Carichi!D:D)="", B29, _xlfn.XLOOKUP(A29,Carichi!B:B,Carichi!D:D) ), B29 ) -> 38.61 | D29: 3 | E29: =D29 +SUMIF(Carichi!B:B,A29,Carichi!C:C)-F29+G29 -> 0 | F29: =SUMIF(Ordini!E:E,TRIM(A29),Ordini!F:F) -> 3 | G29: =SUMIFS(Ordini!N:N,Ordini!E:E,A29,Ordini!M:M,"Reso")+SUMIFS(Ordini!N:N,Ordini!E:E,A29,Ordini!M:M,"RimborsatoReso") -> 0 | H29: 10 | I29: =IFERROR(SUMIFS(Ordini!F:F,Ordini!E:E,A29)/30,1) -> 0.1 | J29: =IF(I29<=0,"NESSUNA ROTAZIONE","ROT: 1 pz ogni "&ROUND(1/I29,0)&" gg") -> ROT: 1 pz ogni 10 gg | K29: =IF(OR('Prodotti Magazzino'!$I29=0,'Prodotti Magazzino'!$I29=""), "NESSUNA VENDITA", ROUND('Prodotti Magazzino'!$E29/'Prodotti Magazzino'!$I29,0) ) -> 0 | L29: =ROUND(IF('Prodotti Magazzino'!$I29<=0,0,'Prodotti Magazzino'!$I29*('Prodotti Magazzino'!$H29+7)),0) -> 2 | M29: =ROUND(MAX(0,(I29*(H29+14))-E29),0) -> 2 | N29: =IF(E29 < I29*H29,"ORDINA SUBITO", IF(E29 < I29*(H29+14),"PREPARA", "OK")) -> ORDINA SUBITO | O29: ='Prodotti Magazzino'!$E29*'Prodotti Magazzino'!$B29 -> 0
A30: Barra e lama - KD10152 | B30: =5.58+2.5 -> 8.08 | C30: =IFERROR( IF(_xlfn.XLOOKUP(A30,Carichi!B:B,Carichi!D:D)="", B30, _xlfn.XLOOKUP(A30,Carichi!B:B,Carichi!D:D) ), B30 ) -> 8.08 | D30: 2 | E30: =D30 +SUMIF(Carichi!B:B,A30,Carichi!C:C)-F30+G30 -> 0 | F30: =SUMIF(Ordini!E:E,TRIM(A30),Ordini!F:F) -> 2 | G30: =SUMIFS(Ordini!N:N,Ordini!E:E,A30,Ordini!M:M,"Reso")+SUMIFS(Ordini!N:N,Ordini!E:E,A30,Ordini!M:M,"RimborsatoReso") -> 0 | H30: 10 | I30: =IFERROR(SUMIFS(Ordini!F:F,Ordini!E:E,A30)/30,1) -> 0.066666667 | J30: =IF(I30<=0,"NESSUNA ROTAZIONE","ROT: 1 pz ogni "&ROUND(1/I30,0)&" gg") -> ROT: 1 pz ogni 15 gg | K30: =IF(OR('Prodotti Magazzino'!$I30=0,'Prodotti Magazzino'!$I30=""), "NESSUNA VENDITA", ROUND('Prodotti Magazzino'!$E30/'Prodotti Magazzino'!$I30,0) ) -> 0 | L30: =ROUND(IF('Prodotti Magazzino'!$I30<=0,0,'Prodotti Magazzino'!$I30*('Prodotti Magazzino'!$H30+7)),0) -> 1 | M30: =ROUND(MAX(0,(I30*(H30+14))-E30),0) -> 2 | N30: =IF(E30 < I30*H30,"ORDINA SUBITO", IF(E30 < I30*(H30+14),"PREPARA", "OK")) -> ORDINA SUBITO | O30: ='Prodotti Magazzino'!$E30*'Prodotti Magazzino'!$B30 -> 0
A31: Motosega a batteria 12" - KD5125 | B31: =32.05 -> 32.05 | C31: =IFERROR( IF(_xlfn.XLOOKUP(A31,Carichi!B:B,Carichi!D:D)="", B31, _xlfn.XLOOKUP(A31,Carichi!B:B,Carichi!D:D) ), B31 ) -> 32.05 | D31: 8 | E31: =D31 +SUMIF(Carichi!B:B,A31,Carichi!C:C)-F31+G31 -> 0 | F31: =SUMIF(Ordini!E:E,TRIM(A31),Ordini!F:F) -> 8 | G31: =SUMIFS(Ordini!N:N,Ordini!E:E,A31,Ordini!M:M,"Reso")+SUMIFS(Ordini!N:N,Ordini!E:E,A31,Ordini!M:M,"RimborsatoReso") -> 0 | H31: 10 | I31: =IFERROR(SUMIFS(Ordini!F:F,Ordini!E:E,A31)/30,1) -> 0.26666667 | J31: =IF(I31<=0,"NESSUNA ROTAZIONE","ROT: 1 pz ogni "&ROUND(1/I31,0)&" gg") -> ROT: 1 pz ogni 4 gg | K31: =IF(OR('Prodotti Magazzino'!$I31=0,'Prodotti Magazzino'!$I31=""), "NESSUNA VENDITA", ROUND('Prodotti Magazzino'!$E31/'Prodotti Magazzino'!$I31,0) ) -> 0 | L31: =ROUND(IF('Prodotti Magazzino'!$I31<=0,0,'Prodotti Magazzino'!$I31*('Prodotti Magazzino'!$H31+7)),0) -> 5 | M31: =ROUND(MAX(0,(I31*(H31+14))-E31),0) -> 6 | N31: =IF(E31 < I31*H31,"ORDINA SUBITO", IF(E31 < I31*(H31+14),"PREPARA", "OK")) -> ORDINA SUBITO | O31: ='Prodotti Magazzino'!$E31*'Prodotti Magazzino'!$B31 -> 0
A32: Kit messa in fase motori diesel - KD12526 | B32: =6.18 -> 6.18 | C32: =IFERROR( IF(_xlfn.XLOOKUP(A32,Carichi!B:B,Carichi!D:D)="", B32, _xlfn.XLOOKUP(A32,Carichi!B:B,Carichi!D:D) ), B32 ) -> 8.82 | D32: 8 | E32: =D32 +SUMIF(Carichi!B:B,A32,Carichi!C:C)-F32+G32 -> 0 | F32: =SUMIF(Ordini!E:E,TRIM(A32),Ordini!F:F) -> 14 | G32: =SUMIFS(Ordini!N:N,Ordini!E:E,A32,Ordini!M:M,"Reso")+SUMIFS(Ordini!N:N,Ordini!E:E,A32,Ordini!M:M,"RimborsatoReso") -> 0 | H32: 10 | I32: =IFERROR(SUMIFS(Ordini!F:F,Ordini!E:E,A32)/30,1) -> 0.46666667 | J32: =IF(I32<=0,"NESSUNA ROTAZIONE","ROT: 1 pz ogni "&ROUND(1/I32,0)&" gg") -> ROT: 1 pz ogni 2 gg | K32: =IF(OR('Prodotti Magazzino'!$I32=0,'Prodotti Magazzino'!$I32=""), "NESSUNA VENDITA", ROUND('Prodotti Magazzino'!$E32/'Prodotti Magazzino'!$I32,0) ) -> 0 | L32: =ROUND(IF('Prodotti Magazzino'!$I32<=0,0,'Prodotti Magazzino'!$I32*('Prodotti Magazzino'!$H32+7)),0) -> 8 | M32: =ROUND(MAX(0,(I32*(H32+14))-E32),0) -> 11 | N32: =IF(E32 < I32*H32,"ORDINA SUBITO", IF(E32 < I32*(H32+14),"PREPARA", "OK")) -> ORDINA SUBITO | O32: ='Prodotti Magazzino'!$E32*'Prodotti Magazzino'!$B32 -> 0
A33: Fresa a tazza - KD12640 | B33: =14.47 -> 14.47 | C33: =IFERROR( IF(_xlfn.XLOOKUP(A33,Carichi!B:B,Carichi!D:D)="", B33, _xlfn.XLOOKUP(A33,Carichi!B:B,Carichi!D:D) ), B33 ) -> 17.03 | D33: 13 | E33: =D33 +SUMIF(Carichi!B:B,A33,Carichi!C:C)-F33+G33 -> 0 | F33: =SUMIF(Ordini!E:E,TRIM(A33),Ordini!F:F) -> 23 | G33: =SUMIFS(Ordini!N:N,Ordini!E:E,A33,Ordini!M:M,"Reso")+SUMIFS(Ordini!N:N,Ordini!E:E,A33,Ordini!M:M,"RimborsatoReso") -> 0 | H33: 10 | I33: =IFERROR(SUMIFS(Ordini!F:F,Ordini!E:E,A33)/30,1) -> 0.76666667 | J33: =IF(I33<=0,"NESSUNA ROTAZIONE","ROT: 1 pz ogni "&ROUND(1/I33,0)&" gg") -> ROT: 1 pz ogni 1 gg | K33: =IF(OR('Prodotti Magazzino'!$I33=0,'Prodotti Magazzino'!$I33=""), "NESSUNA VENDITA", ROUND('Prodotti Magazzino'!$E33/'Prodotti Magazzino'!$I33,0) ) -> 0 | L33: =ROUND(IF('Prodotti Magazzino'!$I33<=0,0,'Prodotti Magazzino'!$I33*('Prodotti Magazzino'!$H33+7)),0) -> 13 | M33: =ROUND(MAX(0,(I33*(H33+14))-E33),0) -> 18 | N33: =IF(E33 < I33*H33,"ORDINA SUBITO", IF(E33 < I33*(H33+14),"PREPARA", "OK")) -> ORDINA SUBITO | O33: ='Prodotti Magazzino'!$E33*'Prodotti Magazzino'!$B33 -> 0
A34: Decespugliatore a scoppio - KD5044 | B34: =50 -> 50 | C34: =IFERROR( IF(_xlfn.XLOOKUP(A34,Carichi!B:B,Carichi!D:D)="", B34, _xlfn.XLOOKUP(A34,Carichi!B:B,Carichi!D:D) ), B34 ) -> 50 | D34: 32 | E34: =D34 +SUMIF(Carichi!B:B,A34,Carichi!C:C)-F34+G34 -> 0 | F34: =SUMIF(Ordini!E:E,TRIM(A34),Ordini!F:F) -> 32 | G34: =SUMIFS(Ordini!N:N,Ordini!E:E,A34,Ordini!M:M,"Reso")+SUMIFS(Ordini!N:N,Ordini!E:E,A34,Ordini!M:M,"RimborsatoReso") -> 0 | H34: 10 | I34: =IFERROR(SUMIFS(Ordini!F:F,Ordini!E:E,A34)/30,1) -> 1.0666667 | J34: =IF(I34<=0,"NESSUNA ROTAZIONE","ROT: 1 pz ogni "&ROUND(1/I34,0)&" gg") -> ROT: 1 pz ogni 1 gg | K34: =IF(OR('Prodotti Magazzino'!$I34=0,'Prodotti Magazzino'!$I34=""), "NESSUNA VENDITA", ROUND('Prodotti Magazzino'!$E34/'Prodotti Magazzino'!$I34,0) ) -> 0 | L34: =ROUND(IF('Prodotti Magazzino'!$I34<=0,0,'Prodotti Magazzino'!$I34*('Prodotti Magazzino'!$H34+7)),0) -> 18 | M34: =ROUND(MAX(0,(I34*(H34+14))-E34),0) -> 26 | N34: =IF(E34 < I34*H34,"ORDINA SUBITO", IF(E34 < I34*(H34+14),"PREPARA", "OK")) -> ORDINA SUBITO | O34: ='Prodotti Magazzino'!$E34*'Prodotti Magazzino'!$B34 -> 0
A35: Trapano a collonna - KD501 | B35: =56.93 -> 56.93 | C35: =IFERROR( IF(_xlfn.XLOOKUP(A35,Carichi!B:B,Carichi!D:D)="", B35, _xlfn.XLOOKUP(A35,Carichi!B:B,Carichi!D:D) ), B35 ) -> 56.93 | D35: 0 | E35: =D35 +SUMIF(Carichi!B:B,A35,Carichi!C:C)-F35+G35 -> 0 | F35: =SUMIF(Ordini!E:E,TRIM(A35),Ordini!F:F) -> 0 | G35: =SUMIFS(Ordini!N:N,Ordini!E:E,A35,Ordini!M:M,"Reso")+SUMIFS(Ordini!N:N,Ordini!E:E,A35,Ordini!M:M,"RimborsatoReso") -> 0 | H35: 10 | I35: =IFERROR(SUMIFS(Ordini!F:F,Ordini!E:E,A35)/30,1) -> 0 | J35: =IF(I35<=0,"NESSUNA ROTAZIONE","ROT: 1 pz ogni "&ROUND(1/I35,0)&" gg") -> NESSUNA ROTAZIONE | K35: =IF(OR('Prodotti Magazzino'!$I35=0,'Prodotti Magazzino'!$I35=""), "NESSUNA VENDITA", ROUND('Prodotti Magazzino'!$E35/'Prodotti Magazzino'!$I35,0) ) -> NESSUNA VENDITA | L35: =ROUND(IF('Prodotti Magazzino'!$I35<=0,0,'Prodotti Magazzino'!$I35*('Prodotti Magazzino'!$H35+7)),0) -> 0 | M35: =ROUND(MAX(0,(I35*(H35+14))-E35),0) -> 0 | N35: =IF(E35 < I35*H35,"ORDINA SUBITO", IF(E35 < I35*(H35+14),"PREPARA", "OK")) -> OK | O35: ='Prodotti Magazzino'!$E35*'Prodotti Magazzino'!$B35 -> 0
A36: Arretratore Pistoncini Freni - KD10784 | B36: =6.95 -> 6.95 | C36: =IFERROR( IF(_xlfn.XLOOKUP(A36,Carichi!B:B,Carichi!D:D)="", B36, _xlfn.XLOOKUP(A36,Carichi!B:B,Carichi!D:D) ), B36 ) -> 6.95 | D36: 0 | E36: =D36 +SUMIF(Carichi!B:B,A36,Carichi!C:C)-F36+G36 -> 0 | F36: =SUMIF(Ordini!E:E,TRIM(A36),Ordini!F:F) -> 0 | G36: =SUMIFS(Ordini!N:N,Ordini!E:E,A36,Ordini!M:M,"Reso")+SUMIFS(Ordini!N:N,Ordini!E:E,A36,Ordini!M:M,"RimborsatoReso") -> 0 | H36: 10 | I36: =IFERROR(SUMIFS(Ordini!F:F,Ordini!E:E,A36)/30,1) -> 0 | J36: =IF(I36<=0,"NESSUNA ROTAZIONE","ROT: 1 pz ogni "&ROUND(1/I36,0)&" gg") -> NESSUNA ROTAZIONE | K36: =IF(OR('Prodotti Magazzino'!$I36=0,'Prodotti Magazzino'!$I36=""), "NESSUNA VENDITA", ROUND('Prodotti Magazzino'!$E36/'Prodotti Magazzino'!$I36,0) ) -> NESSUNA VENDITA | L36: =ROUND(IF('Prodotti Magazzino'!$I36<=0,0,'Prodotti Magazzino'!$I36*('Prodotti Magazzino'!$H36+7)),0) -> 0 | M36: =ROUND(MAX(0,(I36*(H36+14))-E36),0) -> 0 | N36: =IF(E36 < I36*H36,"ORDINA SUBITO", IF(E36 < I36*(H36+14),"PREPARA", "OK")) -> OK | O36: ='Prodotti Magazzino'!$E36*'Prodotti Magazzino'!$B36 -> 0
A37: Tagliasiepe a batteria - KD5092 | B37: =26.82 -> 26.82 | C37: =IFERROR( IF(_xlfn.XLOOKUP(A37,Carichi!B:B,Carichi!D:D)="", B37, _xlfn.XLOOKUP(A37,Carichi!B:B,Carichi!D:D) ), B37 ) -> 29.26 | D37: 1 | E37: =D37 +SUMIF(Carichi!B:B,A37,Carichi!C:C)-F37+G37 -> 1 | F37: =SUMIF(Ordini!E:E,TRIM(A37),Ordini!F:F) -> 20 | G37: =SUMIFS(Ordini!N:N,Ordini!E:E,A37,Ordini!M:M,"Reso")+SUMIFS(Ordini!N:N,Ordini!E:E,A37,Ordini!M:M,"RimborsatoReso") -> 0 | H37: 10 | I37: =IFERROR(SUMIFS(Ordini!F:F,Ordini!E:E,A37)/30,1) -> 0.66666667 | J37: =IF(I37<=0,"NESSUNA ROTAZIONE","ROT: 1 pz ogni "&ROUND(1/I37,0)&" gg") -> ROT: 1 pz ogni 2 gg | K37: =IF(OR('Prodotti Magazzino'!$I37=0,'Prodotti Magazzino'!$I37=""), "NESSUNA VENDITA", ROUND('Prodotti Magazzino'!$E37/'Prodotti Magazzino'!$I37,0) ) -> 2 | L37: =ROUND(IF('Prodotti Magazzino'!$I37<=0,0,'Prodotti Magazzino'!$I37*('Prodotti Magazzino'!$H37+7)),0) -> 11 | M37: =ROUND(MAX(0,(I37*(H37+14))-E37),0) -> 15 | N37: =IF(E37 < I37*H37,"ORDINA SUBITO", IF(E37 < I37*(H37+14),"PREPARA", "OK")) -> ORDINA SUBITO | O37: ='Prodotti Magazzino'!$E37*'Prodotti Magazzino'!$B37 -> 26.82
A38: Decespugliatore a batteria - KD5124 | B38: =11.21+3.89 -> 15.1 | C38: =IFERROR( IF(_xlfn.XLOOKUP(A38,Carichi!B:B,Carichi!D:D)="", B38, _xlfn.XLOOKUP(A38,Carichi!B:B,Carichi!D:D) ), B38 ) -> 15.1 | D38: 25 | E38: =D38 +SUMIF(Carichi!B:B,A38,Carichi!C:C)-F38+G38 -> 0 | F38: =SUMIF(Ordini!E:E,TRIM(A38),Ordini!F:F) -> 25 | G38: =SUMIFS(Ordini!N:N,Ordini!E:E,A38,Ordini!M:M,"Reso")+SUMIFS(Ordini!N:N,Ordini!E:E,A38,Ordini!M:M,"RimborsatoReso") -> 0 | H38: 10 | I38: =IFERROR(SUMIFS(Ordini!F:F,Ordini!E:E,A38)/30,1) -> 0.83333333 | J38: =IF(I38<=0,"NESSUNA ROTAZIONE","ROT: 1 pz ogni "&ROUND(1/I38,0)&" gg") -> ROT: 1 pz ogni 1 gg | K38: =IF(OR('Prodotti Magazzino'!$I38=0,'Prodotti Magazzino'!$I38=""), "NESSUNA VENDITA", ROUND('Prodotti Magazzino'!$E38/'Prodotti Magazzino'!$I38,0) ) -> 0 | L38: =ROUND(IF('Prodotti Magazzino'!$I38<=0,0,'Prodotti Magazzino'!$I38*('Prodotti Magazzino'!$H38+7)),0) -> 14 | M38: =ROUND(MAX(0,(I38*(H38+14))-E38),0) -> 20 | N38: =IF(E38 < I38*H38,"ORDINA SUBITO", IF(E38 < I38*(H38+14),"PREPARA", "OK")) -> ORDINA SUBITO | O38: ='Prodotti Magazzino'!$E38*'Prodotti Magazzino'!$B38 -> 0
A39: Crick auto 2,5 T - WDS2490 | B39: =20.14+3.89 -> 24.03 | C39: =IFERROR( IF(_xlfn.XLOOKUP(A39,Carichi!B:B,Carichi!D:D)="", B39, _xlfn.XLOOKUP(A39,Carichi!B:B,Carichi!D:D) ), B39 ) -> 24.03 | D39: 14 | E39: =D39 +SUMIF(Carichi!B:B,A39,Carichi!C:C)-F39+G39 -> 0 | F39: =SUMIF(Ordini!E:E,TRIM(A39),Ordini!F:F) -> 14 | G39: =SUMIFS(Ordini!N:N,Ordini!E:E,A39,Ordini!M:M,"Reso")+SUMIFS(Ordini!N:N,Ordini!E:E,A39,Ordini!M:M,"RimborsatoReso") -> 0 | H39: 10 | I39: =IFERROR(SUMIFS(Ordini!F:F,Ordini!E:E,A39)/30,1) -> 0.46666667 | J39: =IF(I39<=0,"NESSUNA ROTAZIONE","ROT: 1 pz ogni "&ROUND(1/I39,0)&" gg") -> ROT: 1 pz ogni 2 gg | K39: =IF(OR('Prodotti Magazzino'!$I39=0,'Prodotti Magazzino'!$I39=""), "NESSUNA VENDITA", ROUND('Prodotti Magazzino'!$E39/'Prodotti Magazzino'!$I39,0) ) -> 0 | L39: =ROUND(IF('Prodotti Magazzino'!$I39<=0,0,'Prodotti Magazzino'!$I39*('Prodotti Magazzino'!$H39+7)),0) -> 8 | M39: =ROUND(MAX(0,(I39*(H39+14))-E39),0) -> 11 | N39: =IF(E39 < I39*H39,"ORDINA SUBITO", IF(E39 < I39*(H39+14),"PREPARA", "OK")) -> ORDINA SUBITO | O39: ='Prodotti Magazzino'!$E39*'Prodotti Magazzino'!$B39 -> 0
A40: Motozappa 52cc - KD5162 | B40: 64.8 | C40: =IFERROR( IF(_xlfn.XLOOKUP(A40,Carichi!B:B,Carichi!D:D)="", B40, _xlfn.XLOOKUP(A40,Carichi!B:B,Carichi!D:D) ), B40 ) -> 66.23 | D40: 5 | E40: =D40 +SUMIF(Carichi!B:B,A40,Carichi!C:C)-F40+G40 -> -2 | F40: =SUMIF(Ordini!E:E,TRIM(A40),Ordini!F:F) -> 27 | G40: =SUMIFS(Ordini!N:N,Ordini!E:E,A40,Ordini!M:M,"Reso")+SUMIFS(Ordini!N:N,Ordini!E:E,A40,Ordini!M:M,"RimborsatoReso") -> 0 | H40: 10 | I40: =IFERROR(SUMIFS(Ordini!F:F,Ordini!E:E,A40)/30,1) -> 0.9 | J40: =IF(I40<=0,"NESSUNA ROTAZIONE","ROT: 1 pz ogni "&ROUND(1/I40,0)&" gg") -> ROT: 1 pz ogni 1 gg | K40: =IF(OR('Prodotti Magazzino'!$I40=0,'Prodotti Magazzino'!$I40=""), "NESSUNA VENDITA", ROUND('Prodotti Magazzino'!$E40/'Prodotti Magazzino'!$I40,0) ) -> -2 | L40: =ROUND(IF('Prodotti Magazzino'!$I40<=0,0,'Prodotti Magazzino'!$I40*('Prodotti Magazzino'!$H40+7)),0) -> 15 | M40: =ROUND(MAX(0,(I40*(H40+14))-E40),0) -> 24 | N40: =IF(E40 < I40*H40,"ORDINA SUBITO", IF(E40 < I40*(H40+14),"PREPARA", "OK")) -> ORDINA SUBITO | O40: ='Prodotti Magazzino'!$E40*'Prodotti Magazzino'!$B40 -> -129.6
...

Sheet Colonne dati
B1: Tutti
B2: Pagato | C2: → Spedizione andata
B3: Reso | C3: → Spedizione andata + Spedizione reso
B4: RimborsatoReso | C4: → Spedizione andata
B5: RimborsatoNoReso | C5: → Spedizione andata + Spedizione reso
B6: Non pagato | C6: → Spedizione andata
B7: 0
B8: 0.22
B9: 0.19
B10: 0.2
B11: Tutti | D11: Tutti
B12: Amazon | D12: IT
B13: Temu | D13: DE
B14: eBay | D14: FR
B15: Leroy Merlin | D15: ES
B16: eBay

Sheet Carichi
A1: Data | B1: Prodotto (SKU o nome) | C1: Quantità | D1: Costo aggiornato
A2: 46158 | B2: Miscelatore Per Malta - KD541 | C2: 20 | D2: =20.25+2.7 -> 22.95
A3: 46158 | B3: Tagliasiepe a batteria - KD5092 | C3: 10 | D3: 29.26
A4: 46158 | B4: Irroratore a pressione - KD2033 | C4: 15 | D4: 6.9
A5: 46158 | B5: Motore A Scoppio 210cc - KD1825 | C5: 6 | D5: 43.59
A6: 46158 | B6: Fresa a tazza - KD12640 | C6: 10 | D6: 17.03
A7: 46158 | B7: Kit messa in fase motori diesel - KD12526 | C7: 6 | D7: 8.82
A8: 46158 | B8: Motosega a Scoppio 58cc - KD10613 | C8: 25 | D8: 42.63
A9: 46158 | B9: Fornello a gas - KD10499 | C9: 10 | D9: 8.43
A10: 46179 | B10: Motozappa 52cc - KD5162 | C10: 20 | D10: 66.23
A11: 46179 | B11: Tagliasiepe a batteria - KD5092 | C11: 10 | D11: =26.68+3.8 -> 30.48
A12: 46179 | B12: Irroratore a pressione - KD2033 | C12: 20 | D12: =4.22+3.83 -> 8.05
A13: 46179 | B13: Motosega a Scoppio 58cc - KD10613 | C13: 15 | D13: =40.12+3.83 -> 43.95
A14: 46179 | B14: Fornello a gas - KD10499 | C14: 20 | D14: =5.76+3.83 -> 9.59

Sheet Logistica
A1: Prodotto (SKU o nome) | B1: Paese | C1: Spedizione andata | D1: Spedizione reso | E1: Note
A2: Smerigliatrice angolare - WDS2135 | B2: IT | C2: 4.76 | D2: 4.76
A3: Compressore a batteria - KD5497 | B3: IT | C3: 4.77 | D3: 4.77
A4: Miscelatore Per Malta - KD541 | B4: IT | C4: 4.85 | D4: 4.85
A5: Fornello Elettrico Portatile - KD4139 | B5: IT | C5: 4.77 | D5: 4.77
A6: Cuociuova in Acciaio Inox - KD4118 | B6: IT | C6: 4.77 | D6: 4.77
